Workbook

Sheet Cover
B2: Kelen: business plan model
B3: B2B neobank for SMEs in Senegal, then Côte d'Ivoire. Five years, monthly, every figure driven by formulas.
B5: How to use
B6: 1. Pick a scenario | C6: Assumptions › cell D4: 1 = Prudent, 2 = Base, 3 = Ambitious. Rows with three values switch with it.
B7: 2. Change any input | C7: Inputs are blue on a cream background (Assumptions, Hiring plan, Market). Everything else is a formula: do not type over it.
B8: 3. Change the team | C8: Hiring plan: the fixed roles (founder, CTO, financial expert, sales lead, marketing, country manager, compliance officer). Support, developers, field sales reps and credit analysts grow with clients and the loan book: ratios on Assumptions, section 8.
B9: 4. Check the cash | C9: Dashboard › checks. If cash goes negative, raise more or earlier (Assumptions, section 11).
B11: Tabs
B12: Dashboard | C12: Headline numbers, year-by-year summary and checks.
B13: Plans | C13: The three plans with their prices, limits and features; add-ons, commissions, what is always free, partner income, credit rates and the A/B/C pricing options.
B14: Assumptions | C14: Every hypothesis with its source: timing, acquisition, pricing, usage per client, cost to serve, credit, team and tools, Maak, fixed costs by year, funding.
B15: Unit costs | C15: What one of each thing costs or earns: one employee by role, one client by plan, one loan, and the price of every fixed item.
B16: Hiring plan | C16: Fixed roles, start months and salaries (employer cost = gross + 30% charges); 'Agency hire' adds the €800 agency fee.
B17: Staff | C17: Headcount and employer cost by month: fixed roles plus the team that grows with volume.
B18: Sales & marketing | C18: New clients by channel (field sales, partners, digital) and country; marketing budget; cost to acquire a client.
B19: Clients & revenue | C19: Active clients by plan, usage (cards, balances, payroll, payouts) and every non-credit revenue line.
B20: Credit | C20: Loan book by product, interest, cost of funds, losses and the share kept by Kelen; cash tied up by credit.
B21: Costs | C21: Variable costs, fixed costs by category and the contingency, month by month.
B22: P&L monthly | C22: Revenue, cost of revenue, gross margin, operating expenses, EBITDA, tax, net income (no depreciation: equipment is expensed).
B23: P&L annual | C23: Years 1–5, cash and funding, operating figures and a euro view.
... B29: Regulatory path | C29: What each stage requires from regulators, and where its cost sits in the model.
B31: Colour code
B32: Blue on cream | C32: Input: change freely.
B33: Black | C33: Formula on the same sheet.
B34: Green | C34: Link to another sheet.
B36: Main caveats
B37: Estimates to replace | C37: Every cost line was checked against published prices and proxies in the cost research (Oct 2026, research/costs). Partner bank fees, card processing, Visa/Mastercard fees, PI-SPI business pricing (transfers to wallets) and FX costs have no public price: prudent uses public prices, base the researched value, ambitious negotiated targets. Replace them with term sheets.
B38: Partner income | C38: Interchange and a share of bank income on balances go to the partner bank. No partner has agreed to share them, so the plan counts zero; Pricing levers shows what they would add.
B39: Taxes | C39: Amounts exclude VAT and the 17% tax on financial activities (TAF), which apply to fees. Corporate tax is simplified (30%, losses carried forward without limit).
B40: Côte d'Ivoire | C40: Same 30% employer charges as Senegal; the number of formal employers is an estimate.
B41: Credit | C41: No loans before month 18. A partner microfinance institution (SFD) lends at 23% a year, under the 24% SFD usury cap. Kelen buys an SFD around month 24 and lends from it in Senegal; Côte d'Ivoire loans stay with a partner. The loan book is funded by debt lines, not equity.
B42: Licences | C42: Kelen holds no licence of its own until the SFD acquisition: partners hold the accounts, cards and loans. See Regulatory path.
B43: Sources | C43: Business model v2, Cost breakdown in euros, Senegal launch plan, the market and competitor analysis (Oct 2026, research/market) and the research notes in this project, plus IPRES/ANSD 2024, CNPS and CEPICI 2025 for the market.

Sheet Dashboard
A1: Kelen business plan: dashboard
A2: Key results for the scenario selected on Assumptions. FCFA in columns B–H, euros in column D (headline) and J–N (year by year).
A4: Scenario | B4: =Assumptions!E4 -> Base
A6: Headline numbers
A7: First month with positive EBITDA | B7: =IF(MIN('P&L monthly'!E52:BL52)=999,"not reached",MIN('P&L monthly'!E52:BL52)) -> 22 | C7: month #
A8: which is | B8: =IF(ISNUMBER(B7),DATE(YEAR(Start_Date),MONTH(Start_Date)+B7-1,1),"-") -> 47027
A9: Peak funding need (lowest cumulative cash flow before funding) | B9: =-MIN(0,MIN('Cash flow'!E16:BL16)) -> 1.3189569e+09 | C9: FCFA
A10: in euros | B10: =B9/FX_EUR -> 2010736.8 | C10: €
A11: Equity raised in the plan | B11: =SUM('Cash flow'!E19:BL19) -> 3300000000 | C11: FCFA
A12: in euros | B12: =B11/FX_EUR -> 5030817.6 | C12: €
A13: Lowest closing cash | B13: =MIN('Cash flow'!E24:BL24) -> 4.2398929e+08 | C13: FCFA | D13: =B13/FX_EUR -> 646367.51 | E13: =IF(B13<0,"Cash goes negative: raise more or earlier (Assumptions, section 11)","OK: cash stays positive") -> OK: cash stays positive
A14: in month | B14: =MATCH(B13,'Cash flow'!E24:BL24,0) -> 14 | C14: month #
A15: Cash at the end of year 5 | B15: ='Cash flow'!BL24 -> 6.0199078e+09 | C15: FCFA | D15: =B15/FX_EUR -> 9177290.2
A16: Technology from Maak | B16: =IF(Maak_Option=1,"Lease (option 1)","Equity stake (option 2)") -> Lease (option 1)
A17: Maak's stake in Kelen | B17: =IF(Maak_Option=2,Maak_Equity_Pct,0) -> 0
A18: Year by year
A19: Year | D19: ='P&L annual'!D5 -> 2027 | E19: ='P&L annual'!E5 -> 2028 | F19: ='P&L annual'!F5 -> 2029 | G19: ='P&L annual'!G5 -> 2030 | H19: ='P&L annual'!H5 -> 2031 | J19: ="Y"&1&" (€)" -> Y1 (€) | K19: ="Y"&2&" (€)" -> Y2 (€) | L19: ="Y"&3&" (€)" -> Y3 (€) | M19: ="Y"&4&" (€)" -> Y4 (€) | N19: ="Y"&5&" (€)" -> Y5 (€)
A20: Active clients (end of year) | B20: clients | D20: ='P&L annual'!D56 -> 388.38296 | E20: ='P&L annual'!E56 -> 1419.3994 | F20: ='P&L annual'!F56 -> 3304.4665 | G20: ='P&L annual'!G56 -> 5992.067 | H20: ='P&L annual'!H56 -> 9412.6103
A21: New clients in the year | B21: clients | D21: ='P&L annual'!D59 -> 410.91308 | E21: ='P&L annual'!E59 -> 1187.3569 | F21: ='P&L annual'!F59 -> 2326.8155 | G21: ='P&L annual'!G59 -> 3562.2927 | H21: ='P&L annual'!H59 -> 4883.0227
A22: Headcount (end of year) | B22: people | D22: ='P&L annual'!D60 -> 11 | E22: ='P&L annual'!E60 -> 19 | F22: ='P&L annual'!F60 -> 33 | G22: ='P&L annual'!G60 -> 51 | H22: ='P&L annual'!H60 -> 75
A23: Total revenue | B23: FCFA | D23: ='P&L annual'!D23 -> 1.5558179e+08 | E23: ='P&L annual'!E23 -> 1.1374381e+09 | F23: ='P&L annual'!F23 -> 3.5775977e+09 | G23: ='P&L annual'!G23 -> 7.1694097e+09 | H23: ='P&L annual'!H23 -> 1.2058507e+10 | J23: =D23/FX_EUR -> 237182.9 | K23: =E23/FX_EUR -> 1734013.2 | L23: =F23/FX_EUR -> 5454012.6 | M23: =G23/FX_EUR -> 10929695 | N23: =H23/FX_EUR -> 18383075
A24: Gross margin | B24: FCFA | D24: ='P&L annual'!D32 -> 64078008 | E24: ='P&L annual'!E32 -> 5.2191296e+08 | F24: ='P&L annual'!F32 -> 1.6743827e+09 | G24: ='P&L annual'!G32 -> 3.4049709e+09 | H24: ='P&L annual'!H32 -> 5.746762e+09 | J24: =D24/FX_EUR -> 97686.294 | K24: =E24/FX_EUR -> 795651.18 | L24: =F24/FX_EUR -> 2552580 | M24: =G24/FX_EUR -> 5190844.7 | N24: =H24/FX_EUR -> 8760882.1
A25: Gross margin % | B25: % | D25: ='P&L annual'!D33 -> 0.4118606 | E25: ='P&L annual'!E33 -> 0.45884955 | F25: ='P&L annual'!F33 -> 0.46801873 | G25: ='P&L annual'!G33 -> 0.47493044 | H25: ='P&L annual'!H33 -> 0.47657326
A26: Total operating expenses | B26: FCFA | D26: ='P&L annual'!D44 -> 4.5089034e+08 | E26: ='P&L annual'!E44 -> 7.0054083e+08 | F26: ='P&L annual'!F44 -> 1.0045216e+09 | G26: ='P&L annual'!G44 -> 1.2616374e+09 | H26: ='P&L annual'!H44 -> 1.6332518e+09 | J26: =D26/FX_EUR -> 687377.89 | K26: =E26/FX_EUR -> 1067967.6 | L26: =F26/FX_EUR -> 1531383.3 | M26: =G26/FX_EUR -> 1923353.9 | N26: =H26/FX_EUR -> 2489876.4
A27: EBITDA | B27: FCFA | D27: ='P&L annual'!D45 -> -3.8681233e+08 | E27: ='P&L annual'!E45 -> -1.7862787e+08 | F27: ='P&L annual'!F45 -> 6.6986112e+08 | G27: ='P&L annual'!G45 -> 2.1433335e+09 | H27: ='P&L annual'!H45 -> 4.1135101e+09 | J27: =D27/FX_EUR -> -589691.59 | K27: =E27/FX_EUR -> -272316.43 | L27: =F27/FX_EUR -> 1021196.7 | M27: =G27/FX_EUR -> 3267490.8 | N27: =H27/FX_EUR -> 6271005.8
A28: EBITDA margin | B28: % | D28: ='P&L annual'!D46 -> -2.4862314 | E28: ='P&L annual'!E46 -> -0.15704403 | F28: ='P&L annual'!F46 -> 0.18723769 | G28: ='P&L annual'!G46 -> 0.29895536 | H28: ='P&L annual'!H46 -> 0.34112931
A29: Net income | B29: FCFA | D29: ='P&L annual'!D48 -> -3.8681233e+08 | E29: ='P&L annual'!E48 -> -1.7862787e+08 | F29: ='P&L annual'!F48 -> 6.3853484e+08 | G29: ='P&L annual'!G48 -> 1.5003334e+09 | H29: ='P&L annual'!H48 -> 2.8794571e+09 | J29: =D29/FX_EUR -> -589691.59 | K29: =E29/FX_EUR -> -272316.43 | L29: =F29/FX_EUR -> 973440.09 | M29: =G29/FX_EUR -> 2287243.6 | N29: =H29/FX_EUR -> 4389704
A30: Closing cash | B30: FCFA | D30: ='P&L annual'!D53 -> 4.8318767e+08 | E30: ='P&L annual'!E53 -> 2.008311e+09 | F30: ='P&L annual'!F53 -> 2.3351678e+09 | G30: ='P&L annual'!G53 -> 3.5155775e+09 | H30: ='P&L annual'!H53 -> 6.0199078e+09 | J30: =D30/FX_EUR -> 736614.86 | K30: =E30/FX_EUR -> 3061650.4 | L30: =F30/FX_EUR -> 3559940.4 | M30: =G30/FX_EUR -> 5359463.4 | N30: =H30/FX_EUR -> 9177290.2
A31: Loan book (end of year) | B31: FCFA | D31: ='P&L annual'!D61 -> 0 | E31: ='P&L annual'!E61 -> 4.6248764e+08 | F31: ='P&L annual'!F61 -> 2.6124191e+09 | G31: ='P&L annual'!G61 -> 4.998759e+09 | H31: ='P&L annual'!H61 -> 7.85595e+09 | J31: =D31/FX_EUR -> 0 | K31: =E31/FX_EUR -> 705057.86 | L31: =F31/FX_EUR -> 3982607.3 | M31: =G31/FX_EUR -> 7620558.9 | N31: =H31/FX_EUR -> 11976319
A32: Revenue per active client a month (ARPA) | B32: FCFA / month | D32: ='Unit economics'!D13 -> 88541.5 | E32: ='Unit economics'!E13 -> 107584.33 | F32: ='Unit economics'!F13 -> 123594.36 | G32: ='Unit economics'!G13 -> 126941.22 | H32: ='Unit economics'!H13 -> 128715.15 | J32: =D32/FX_EUR -> 134.98065 | K32: =E32/FX_EUR -> 164.01125 | L32: =F32/FX_EUR -> 188.41839 | M32: =G32/FX_EUR -> 193.52064 | N32: =H32/FX_EUR -> 196.22498
A33: Blended CAC | B33: FCFA / client | D33: ='Unit economics'!D20 -> 203740.15 | E33: ='Unit economics'!E20 -> 118062.58 | F33: ='Unit economics'!F20 -> 98005.214 | G33: ='Unit economics'!G20 -> 88115.755 | H33: ='Unit economics'!H20 -> 86075.16 | J33: =D33/FX_EUR -> 310.59986 | K33: =E33/FX_EUR -> 179.98525 | L33: =F33/FX_EUR -> 149.40798 | M33: =G33/FX_EUR -> 134.3316 | N33: =H33/FX_EUR -> 131.22074
A34: CAC payback (months) | B34: months | D34: ='Unit economics'!D21 -> 5.5870107 | E34: ='Unit economics'!E21 -> 2.3916243 | F34: ='Unit economics'!F21 -> 1.6942882 | G34: ='Unit economics'!G21 -> 1.4615743 | H34: ='Unit economics'!H21 -> 1.4031965
A36: Checks
A37: New-client mix adds up to 100% | B37: =IF(ABS(Mix_Petite+Mix_Moyenne+Mix_Grande-1)<0.0001,"OK","ERROR") -> OK
A38: Cost of revenue in the P&L equals variable costs | B38: =IF(ABS(SUM('P&L monthly'!E30:BL30)-SUM(Costs!E23:BL23))<1,"OK","ERROR") -> OK
A39: Opex in the P&L equals fixed costs | B39: =IF(ABS(SUM('P&L monthly'!E43:BL43)-SUM(Costs!E95:BL95))<1,"OK","ERROR") -> OK
A40: Annual revenue equals monthly revenue | B40: =IF(ABS('P&L annual'!I23-SUM('P&L monthly'!E23:BL23))<1,"OK","ERROR") -> OK
A41: Closing cash never negative | B41: =IF(MIN('Cash flow'!E24:BL24)>=0,"OK","RAISE MORE") -> OK

Sheet Plans
A1: Plans, add-ons and commissions
A2: The offer as clients see it, for the pricing option selected on Assumptions. Every price, limit and fee links to Assumptions; feature rows are the product definition.
A5: The three plans
A6: Clients choose by what they need, not by staff count. Two simple limits: a number of transfers to bank accounts (salaries never count) and an amount sent to mobile money (salaries included).
A7: What is included | B7: Essentiel | C7: Pro | D7: Business | E7: Notes
A8: Price
A9: Monthly price | B9: =Price_Petite -> 9900 | C9: =Price_Moyenne -> 19500 | D9: =Price_Grande -> 69500 | E9: FCFA a month, excluding VAT. Option A / B / C on Assumptions.
A10: in € | B10: =IF(ISNUMBER(B9),B9/FX_EUR,"") -> 15.092453 | C10: =IF(ISNUMBER(C9),C9/FX_EUR,"") -> 29.727558 | D10: =IF(ISNUMBER(D9),D9/FX_EUR,"") -> 105.95207
A11: Yearly billing (price for 12 months) | B11: =Price_Petite*(12-Annual_Free) -> 99000 | C11: =Price_Moyenne*(12-Annual_Free) -> 195000 | D11: =Price_Grande*(12-Annual_Free) -> 695000 | E11: ="Pay yearly and get "&Annual_Free&" months free." -> Pay yearly and get 2 months free.
A12: in € | B12: =IF(ISNUMBER(B11),B11/FX_EUR,"") -> 150.92453 | C12: =IF(ISNUMBER(C11),C11/FX_EUR,"") -> 297.27558 | D12: =IF(ISNUMBER(D11),D11/FX_EUR,"") -> 1059.5207
A13: Free trial | B13: =Free_Months&" month free" -> 1 month free | C13: =Free_Months&" month free" -> 1 month free | D13: =Free_Months&" month free" -> 1 month free | E13: Every new client, every plan.
A14: Limits
A15: Users included | B15: =Users_Incl_Petite -> 2 | C15: =Users_Incl_Moyenne -> 3 | D15: =Users_Incl_Grande -> 10 | E15: Essentiel: 1 main user + 1 invited free. More users: add-on below.
A16: Bank transfers a month | B16: =Transfers_Incl_Petite -> 30 | C16: =Transfers_Incl_Moyenne -> 100 | D16: =Transfers_Incl_Grande -> 400 | E16: Payments to suppliers and others by bank transfer. Salaries and transfers to wallets never count. Above it: fee per extra transfer. Incoming transfers are free and unlimited.
A17: Mobile money free up to | B17: =MM_Free_Petite -> 200000 | C17: =MM_Free_Moyenne -> 1000000 | D17: =MM_Free_Grande -> 5000000 | E17: FCFA a month sent to wallets (Wave, Orange Money, Mixx…), salaries included. Above it: the mobile money fee below. Fair use: no splitting into many tiny transfers.
A18: in € | B18: =IF(ISNUMBER(B17),B17/FX_EUR,"") -> 304.89803 | C18: =IF(ISNUMBER(C17),C17/FX_EUR,"") -> 1524.4902 | D18: =IF(ISNUMBER(D17),D17/FX_EUR,"") -> 7622.4509
A19: Salaries to bank accounts free up to | B19: =Payroll_Free_Petite -> 3000000 | C19: =Payroll_Free_Moyenne -> 15000000 | D19: =Payroll_Free_Grande -> 60000000 | E19: FCFA of salaries a month. Above it: fee per extra transfer for each salary.
A20: in € | B20: =IF(ISNUMBER(B19),B19/FX_EUR,"") -> 4573.4705 | C20: =IF(ISNUMBER(C19),C19/FX_EUR,"") -> 22867.353 | D20: =IF(ISNUMBER(D19),D19/FX_EUR,"") -> 91469.41
A21: Physical cards included | B21: =Cards_Phys_Incl_Petite -> 1 | C21: =Cards_Phys_Incl_Moyenne -> 1 | D21: =Cards_Phys_Incl_Grande -> 1 | E21: Visa cards for staff, co-branded with the partner bank. More cards: one-off fee below.
A22: Virtual cards | B22: 2 | C22: 10 | D22: Unlimited | E22: For online payments: ads, software, subscriptions.
A23: Sub-accounts | B23: 1 | C23: 5 | D23: Unlimited | E23: Separate balances by project, site or budget.
A24: Features
A25: Business account with its own IBAN | B25: ✓ | C25: ✓ | D25: ✓ | E25: Held at the partner bank.
A26: Salary payments to any bank or wallet | B26: ✓ | C26: ✓ | D26: ✓ | E26: Bulk runs, scheduled paydays, status per employee.
A27: Import a payroll file (KayFay, Sage, Excel…) | B27: ✓ | C27: ✓ | D27: ✓
A28: Invoices and payment links (Wave, Orange Money, card) | B28: ✓ | C28: ✓ | D28: ✓ | E28: Commission on mobile-money collections: see commissions.
A29: Approvals (double signature) | B29: — | C29: ✓ | D29: ✓ multi-level, custom rules | E29: Locked on Essentiel: tapping it shows an "Unlock with Pro" button.
A30: Accounting module (accountant access, receipts, SYSCOHADA export) | B30: — | C30: ✓ | D30: ✓ | E30: Locked on Essentiel.
A31: Spend control (limits and budgets per card or person) | B31: — | C31: Basic | D31: Full
A32: API and several companies under one login | B32: — | C32: — | D32: ✓
A33: Support | B33: Chat | C33: Priority | D33: Dedicated adviser
A34: Payroll module (payslips and declarations) | B34: Paid option | C34: Paid option | D34: Paid option | E34: Per payslip: see add-ons.
A35: International supplier payments | B35: ✓ | C35: ✓ | D35: ✓ | E35: Fee per payment: see commissions.
A37: Add-ons
A38: Paid only when a client goes beyond its plan or chooses an option. Upgrade prompts appear at 80% and 100% of each limit.
A39: Add-on | B39: Price | C39: Unit | E39: When it applies
A40: Extra user | B40: =Extra_User_Fee -> 2500 | C40: FCFA / month | E40: Each user beyond the plan.
A41: in € | B41: =IF(ISNUMBER(B40),B40/FX_EUR,"") -> 3.8112254
A42: Extra physical card | B42: =Card_Fee -> 6500 | C42: FCFA, one-off | E42: The first physical card is free; each other card is paid once, for printing and delivery. No monthly fee.
A43: in € | B43: =IF(ISNUMBER(B42),B42/FX_EUR,"") -> 9.9091861
...

Sheet How it works
A1: How Kelen works
A2: Who does what, how the money moves, and when Kelen needs its own cash. Kelen never holds client money: it sits at the partner bank, and later also at Kelen's own SFD.
A5: The partners
A6: Kelen is the app, the onboarding, the support and the controls. The licences, the accounts and the cards belong to partners until Kelen owns an SFD.
A7: Partner | B7: What it does | C7: What Kelen pays it | D7: When
A8: Partner bank | B8: Holds every client account (in the client's name, at the bank), signs off the identity checks, executes transfers (same bank, interbank, PI-SPI, SWIFT), issues the Visa cards under its name and keeps the client money. | C8: A fee per account, a fee per transfer, card programme set-up, and a cash guarantee (collateral) for the cards. | D8: From launch, both countries.
A9: Wave and Orange Money (directly or through an aggregator: HUB2, PayDunya, CinetPay, InTouch) | B9: Deliver transfers to wallets and collect payment-link payments. | C9: 1% per transfer to a wallet today (Wave capped at 5,000 FCFA), about 1% on collections. Aggregators: 1.5–2% public, less with volume. | D9: From launch.
A10: Card processor (HPS, Paymentology, GIM-UEMOA…) | B10: Approves every card payment in real time against the client's balance and handles card files. | C10: A monthly fee per active card. | D10: From the card launch.
A11: Visa / Mastercard | B11: The card network. Paid through the partner bank. | C11: Cross-border fees on payments in other currencies. | D11: From the card launch.
A12: Partner SFD (microfinance institution) | B12: Lends under its licence and with its funding; Kelen finds, scores and services the loans. | C12: Kelen keeps a share of the net margin and puts up a first-loss reserve. | D12: Month 18 to month 24 in Senegal; all along in Côte d'Ivoire.
A13: International payment provider (partner bank, Capi Money or others) | B13: Converts FCFA and pays suppliers abroad in euros, dollars or yuan. | C13: Its rate (about 3.5% assumed); Kelen charges 3.8% plus 1,500 FCFA per payment. The 0.6% tax is passed on to the client. | D13: From month 13.
A14: Maak (group company) | B14: The banking platform: accounts ledger, payments, cards and app back-end. | C14: A lease for 3 years, then upgrades and maintenance. | D14: From month 1.
A16: Service by service
A17: What each side does and how the money moves. 'Cash Kelen must put up' is Kelen's own money, not client money.
A18: Service | B18: Partner bank or SFD does | C18: Kelen does | D18: How the money moves | E18: Cash Kelen must put up
A19: Business account | B19: Opens the account in the client's name and holds the money. | C19: App and web access, onboarding file, identity checks, support. | D19: The client's money stays in the client's account at the bank. | E19: None.
A20: Bank transfers and salaries to bank accounts | B20: Executes the transfer from the client's account: free inside the same bank, through the interbank system or PI-SPI otherwise. | C20: Payment screens, bulk payroll runs, approvals, status per payment. | D20: Client account → recipient's bank account, directly. | E20: None.
A21: Transfers to wallets (salaries and others) | B21: Route 1: sends from the client's account straight to Wave or Orange Money through PI-SPI, if the bank offers business transfers to wallets. | C21: Bulk runs and approvals. Route 2 or 3: Kelen runs the payout through Wave, Orange Money or an aggregator. | D21: Route 1: client account → wallet. Routes 2 and 3: client account → a prefunded business wallet or aggregator balance → employee's wallet. | E21: Route 1: none. Routes 2 and 3: a float covering 1–3 days of payouts, larger on paydays. Not in the plan yet: see the routes below.
A22: Payment links (collections) | B22: Receives the settlement and credits the client's account. | C22: The link, the invoice, matching payments to invoices. | D22: The customer pays by Wave or Orange Money → operator or aggregator merchant account → settled to the bank (same day to 5 days; Orange D+5) → client's account. | E22: None if the client is credited at settlement. A float if Kelen credits instantly.
A23: Cards (co-branded with the partner bank) | B23: Issues the cards under its name and Visa licence, pays Visa every day and debits the client's account. | C23: Card design and ordering, spending limits and controls in the app, first-line disputes. | D23: The client pays → the processor checks the balance and blocks the amount → next day Visa debits the bank → the bank debits the client's account. | E23: Collateral at the bank (60M FCFA in the plan, from month 4). If the bank runs the cards as prepaid, also a float of a few days of card spending.
A24: International payments | B24: Converts and sends the payment (SWIFT), checks the foreign-exchange paperwork. | C24: Collects invoices and import documents, compliance checks, sends the instruction. | D24: Client account debited (amount + fee + 0.6% tax) → provider → supplier abroad. | E24: None if the provider debits on execution; a balance if it needs prefunding.
A25: Payroll module and accounting | B25: Nothing. | C25: Software only: payslips, declarations, accountant access, exports. | D25: No money moves. | E25: None.
A26: Credit, partner SFD (Senegal months 18–24; Côte d'Ivoire) | B26: Signs the loan, lends its money (or debt lines), carries the risk above the first-loss reserve. | C26: Scoring from account data, the loan offer in the app, repayments collected from the account. | D26: SFD → client's account; repayments taken from the account. | E26: First-loss reserve (share of the loan book).
A27: Credit, Kelen's own SFD (Senegal from month 24) | B27: — | C27: Lends itself and keeps the whole margin, under the 24% rate cap. | D27: Kelen's SFD → client's account; repayments back to the SFD. | E27: Equity in the loans (capital ratio) plus debt lines for the rest.
A29: Transfers to mobile money: the three routes
A30: Not every bank can send to wallets today. The route decides the cost and whether Kelen must prefund a float. The plan assumes no deal: 1% capped at 5,000 FCFA.
A31: Route | B31: How it works | C31: Cost today | D31: Cash Kelen must put up | E31: Status
A32: 1. Partner bank through PI-SPI | B32: The bank sends from the client's account straight to the wallet. From 2 November 2026 every interoperable transfer goes through PI-SPI, Wave included. | C32: Set freely by the bank for businesses: to negotiate (capped or flat). | D32: None. | E32: The bank needs PI-SPI business access (bulk payments). Certified in Senegal so far: 9 participants, including Ecobank, which is certified in all 8 countries. Make it a condition when choosing the bank.
A33: 2. Direct contract with Wave Business and Orange Money | B33: A business wallet with each operator, paid out through their API. | C33: Wave 1% (reportedly capped at 5,000 FCFA); Orange 1%, 1.5% to other wallets. | D33: The business wallets must be topped up before payouts (1–3 days of volume, more on paydays). | E33: Possible now. The float is client money in transit: it must sit under a licensed partner's name.
A34: 3. Aggregator (HUB2, PayDunya, CinetPay, InTouch) | B34: One API to every operator. | C34: 1.5–2% public; HUB2 and InTouch on quote, lower with volume. | D34: A prefunded balance at the aggregator. | E34: Possible now; the most expensive public route.
A35: 4. Kelen's own SFD on PI-SPI (after month 24) | B35: SFDs can join PI-SPI (UM ACEP, an SFD, is certified for business payments). | C35: PI-SPI fees only. | D35: The SFD's own settlement account. | E35: Later; depends on the SFD bought.
A37: The card programme
A38: Co-branded, not fully white-label: like Djamo's cards with Ecobank, or Wave's virtual Visa with Ecobank.
A39: Question | B39: Answer
A40: Whose name is on the card? | B40: The partner bank is the issuer (its Visa licence and card number range) and its name is on the card next to Kelen's brand.
A41: Does Kelen need cash for card payments? | B41: Not for the payments themselves: the bank pays Visa and debits the client's account. Kelen puts up collateral (60M FCFA in the plan) so the bank is covered for disputes, fraud or a failed debit. If the bank runs the cards as prepaid, a float of a few days of spending must also be prefunded.
A42: Who earns the interchange? | B42: The bank, as the issuer. Kelen only if the bank agrees to share it: not in the plan.
A43: What does Kelen pay? | B43: The processor per active card, the printing of physical cards, Visa's cross-border fees on foreign payments, and any set-up fee the bank asks.
A44: Can Kelen's own SFD issue cards later? | B44: Not on its own at first: Visa membership needs a bank sponsor or large collateral. The plan keeps the partner bank for cards.
A46: What changes when Kelen owns an SFD (Senegal, from month 24)
...

Sheet Assumptions
A1: Assumptions and hypotheses
A2: Every blue cell on a cream background is an input. Change it and the whole model updates. Amounts in FCFA unless stated. Column D is the value the model uses.
B4: Scenario (1 = Prudent, 2 = Base, 3 = Ambitious) | D4: 2 | E4: =CHOOSE(Scenario,"Prudent","Base","Ambitious") -> Base | I4: Rows with Prudent / Base / Ambitious values switch with this cell.
B7: 1. General | C7: Unit | D7: Value used | E7: Prudent | F7: Base | G7: Ambitious | H7: € / FCFA equivalent | I7: Source / note
B8: Model start (month 1) | C8: date | D8: 46388 | I8: First month of the plan. Company set-up, licence file and product build start here.
B9: FCFA per euro | C9: FCFA | D9: 655.957 | I9: Fixed parity CFA franc / euro (BCEAO).
B10: FCFA per US dollar | C10: FCFA | D10: 580 | I10: Planning rate, used for vendor prices quoted in USD.
B11: Corporate income tax rate | C11: % | D11: 0.3 | I11: Senegal CIT 30%. Simplification: losses carried forward without limit (Senegal allows 3 years). Minimum tax and the 17% TAF on financial services are not modelled.
B12: Annual pay rise (from year 2) | C12: % / year | D12: 0.05 | I12: Applied to every salary each new year.
B13: Contingency on fixed costs | C13: % | D13: 0.05 | I13: Same 5% as the cost breakdown.
B15: 2. Timing (month numbers, 1 = first month of the model) | C15: Unit | D15: Value used | E15: Prudent | F15: Base | G15: Ambitious | H15: € / FCFA equivalent | I15: Source / note
B16: Commercial launch, Senegal | C16: month # | D16: 5 | I16: After partner bank integration and card programme set-up (business account with IBAN via the partner bank).
B17: Commercial launch, Côte d'Ivoire | C17: month # | D17: 19 | I17: One month after the Abidjan office opens. Partners hold the licences in Côte d'Ivoire too.
B18: Dakar office (Regus) from | C18: month # | D18: 1 | I18: Regus from day one: no lease, deposit or fit-out (decision).
B19: Abidjan office (Regus) and first Côte d'Ivoire hires | C19: month # | D19: 18 | I19: Not before month 18 (decision).
B20: Payment links go live | C20: month # | D20: 18 | I20: 'Bientôt' feature in the app.
B21: B2C launch: employee salary accounts and personal accounts | C21: month # | D21: 29 | I21: Not before 2 years of commercial activity: Senegal launch + 24 months (decision).
B22: Acquisition of a microfinance company (SFD) closes | C22: month # | D22: 24 | I22: Around year 2 (decision). Due diligence and the change-of-control approval run during year 2.
B23: Own SFD lends from | C23: month # | D23: 25 | I23: Before this month the partner SFD lends and Kelen keeps a share of the margin. Côte d'Ivoire loans stay with a partner: SFD licences are national.
B24: Card programme collateral at partner bank | C24: month # | D24: 4
B25: Partner bank set-up fee paid, Senegal | C25: month # | D25: 2
B26: Partner bank set-up fee paid, Côte d'Ivoire | C26: month # | D26: 16
B27: Card processor set-up fee paid | C27: month # | D27: 3
B28: Card processor monthly minimum starts | C28: month # | D28: 5
B29: Cloud hosting starts | C29: month # | D29: 2
B30: Partner SFD integration fee paid | C30: month # | D30: 15 | I30: Partner SFD signed early; integration paid before the first loans.
B31: Côte d'Ivoire subsidiary created | C31: month # | D31: 16 | I31: Before the first Abidjan hires.
B32: First tech audit (then every 12 months) | C32: month # | D32: 4 | I32: Before launch, for the partner bank; repeated yearly.
B34: 3. Client acquisition (sales and marketing) | C34: Unit | D34: Value used | E34: Prudent | F34: Base | G34: Ambitious | H34: € / FCFA equivalent | I34: Source / note
B35: New clients signed per field sales rep per month | C35: clients | D35: =CHOOSE(Scenario,E35,F35,G35) -> 8 | E35: 7 | F35: 8 | G35: 13 | I35: Rep counts come from the hiring plan. A rep sells from the month after joining. Base lowered from 10 to 8 after the market analysis (Oct 2026): Julaya had about 2,800 active users in Senegal after six years. Validate in the pilot.
B36: Côte d'Ivoire rep productivity vs Senegal | C36: x | D36: 0.9 | I36: Slightly lower at first: new market, brand unknown.
B37: Partner channel, Senegal: clients a month at launch | C37: clients | D37: =CHOOSE(Scenario,E37,F37,G37) -> 8 | E37: 6 | F37: 8 | G37: 14 | I37: Accountants, payroll software (KayFay, Sage, Odoo), chambers of commerce. Base lowered from 10 to 8 after the market analysis (Oct 2026).
B38: Partner channel, Côte d'Ivoire: clients a month at launch | C38: clients | D38: =CHOOSE(Scenario,E38,F38,G38) -> 6 | E38: 4 | F38: 6 | G38: 9
B39: Partner channel monthly growth | C39: % / month | D39: 0.06
B40: Partner channel cap, Senegal | C40: clients / month | D40: 80
B41: Partner channel cap, Côte d'Ivoire | C41: clients / month | D41: 60
B42: Digital ads cost per signed client | C42: FCFA | D42: =CHOOSE(Scenario,E42,F42,G42) -> 75000 | E42: 100000 | F42: 75000 | G42: 55000 | H42: =D42/FX_EUR -> 114.33676 | I42: Media spend only. Meta leads 600–2,800 FCFA; lead-to-client conversion assumed 2–4%.
B43: Share of new clients on Essentiel (mostly small firms) | C43: % | D43: 0.6 | I43: Plans are chosen by limits and features, not staff count. Small firms (about 5 staff) take Essentiel. The three shares must add up to 100% (see check on the Dashboard).
B44: Share of new clients on Pro (mostly mid-size firms) | C44: % | D44: 0.3 | I44: Firms that need approvals (double signature) or the accounting module, typically 10–50 staff.
B45: Share of new clients on Business (mostly large firms) | C45: % | D45: 0.1
...

Sheet Unit costs
A1: Unit costs and prices
A2: What one of each thing costs or earns, in FCFA with the euro amount on the 'in €' line underneath. Every cell links to the inputs on Assumptions and Hiring plan: change them there.
A5: Each service: what the client pays, what it costs Kelen, what Kelen keeps
A6: One example of each service, in FCFA, at the current scenario's costs. 'Status' says how solid the cost is: quoted, researched (public prices) or estimate. Kelen never pays the 0.6% tax on transfers out of the zone or the transfer tax: they are passed on at cost.
A7: Service (example) | B7: Who Kelen pays | C7: Client pays | D7: Cost to Kelen | E7: Kelen keeps | F7: Margin | G7: Status of the cost
A8: Account and plan
A9: Pro plan, one month (bank fee and messaging only) | B9: Partner bank (fee per account), WhatsApp / SMS | C9: =Price_Moyenne -> 19500 | D9: =Bank_Fee+Notif_Cost -> 1850 | E9: =C9-D9 -> 17650 | F9: =IF(C9>0,E9/C9,"") -> 0.90512821 | G9: Bank fee: estimate, no term sheet yet
A10: in € | C10: =IF(ISNUMBER(C9),C9/FX_EUR,"") -> 29.727558 | D10: =IF(ISNUMBER(D9),D9/FX_EUR,"") -> 2.8203068 | E10: =IF(ISNUMBER(E9),E9/FX_EUR,"") -> 26.907252
A11: Opening a new client (identity checks) | B11: Identity-check vendor | C11: =0 -> 0 | D11: =KYB_Cost+KYC_Cost*KYC_Persons -> 3300 | E11: =C11-D11 -> -3300 | F11: =IF(C11>0,E11/C11,"") | G11: Researched (vendor prices)
A12: in € | C12: =IF(ISNUMBER(C11),C11/FX_EUR,"") -> 0 | D12: =IF(ISNUMBER(D11),D11/FX_EUR,"") -> 5.0308176 | E12: =IF(ISNUMBER(E11),E11/FX_EUR,"") -> -5.0308176
A13: Extra user, one month | B13: Nobody | C13: =Extra_User_Fee -> 2500 | D13: =0 -> 0 | E13: =C13-D13 -> 2500 | F13: =IF(C13>0,E13/C13,"") -> 1
A14: in € | C14: =IF(ISNUMBER(C13),C13/FX_EUR,"") -> 3.8112254 | D14: =IF(ISNUMBER(D13),D13/FX_EUR,"") -> 0 | E14: =IF(ISNUMBER(E13),E13/FX_EUR,"") -> 3.8112254
A15: Transfers
A16: Bank transfer to a supplier, inside the allowance | B16: Partner bank | C16: =0 -> 0 | D16: =Supplier_Payout_Cost -> 150 | E16: =C16-D16 -> -150 | F16: =IF(C16>0,E16/C16,"") | G16: Researched: 150–2,000 FCFA in bank tariffs; same-bank transfers free
A17: in € | C17: =IF(ISNUMBER(C16),C16/FX_EUR,"") -> 0 | D17: =IF(ISNUMBER(D16),D16/FX_EUR,"") -> 0.22867353 | E17: =IF(ISNUMBER(E16),E16/FX_EUR,"") -> -0.22867353
A18: Bank transfer above the allowance | B18: Partner bank | C18: =Overage_Fee -> 450 | D18: =Supplier_Payout_Cost -> 150 | E18: =C18-D18 -> 300 | F18: =IF(C18>0,E18/C18,"") -> 0.66666667 | G18: Researched, as above
A19: in € | C19: =IF(ISNUMBER(C18),C18/FX_EUR,"") -> 0.68602058 | D19: =IF(ISNUMBER(D18),D18/FX_EUR,"") -> 0.22867353 | E19: =IF(ISNUMBER(E18),E18/FX_EUR,"") -> 0.45734705
A20: Salary to a bank account | B20: Partner bank | C20: =0 -> 0 | D20: =Bank_Payout_Cost -> 100 | E20: =C20-D20 -> -100 | F20: =IF(C20>0,E20/C20,"") | G20: Researched, as above
A21: in € | C21: =IF(ISNUMBER(C20),C20/FX_EUR,"") -> 0 | D21: =IF(ISNUMBER(D20),D20/FX_EUR,"") -> 0.15244902 | E21: =IF(ISNUMBER(E20),E20/FX_EUR,"") -> -0.15244902
A22: 75,000 FCFA to a wallet, inside the free amount | B22: Wave / Orange Money (or an aggregator) | C22: =0 -> 0 | D22: =(IF(MM_Cost_Cap>0,MIN(MM_Cost_Pct*75000,MM_Cost_Cap),MM_Cost_Pct*75000)+MM_Cost_Flat) -> 375 | E22: =C22-D22 -> -375 | F22: =IF(C22>0,E22/C22,"") | G22: Public price: 1% (no deal yet)
A23: in € | C23: =IF(ISNUMBER(C22),C22/FX_EUR,"") -> 0 | D23: =IF(ISNUMBER(D22),D22/FX_EUR,"") -> 0.57168381 | E23: =IF(ISNUMBER(E22),E22/FX_EUR,"") -> -0.57168381
A24: 200,000 FCFA salary to a wallet, above the free amount | B24: Wave / Orange Money (or an aggregator) | C24: =MIN(MM_Fee*200000,MM_Fee_Cap) -> 2500 | D24: =(IF(MM_Cost_Cap>0,MIN(MM_Cost_Pct*200000,MM_Cost_Cap),MM_Cost_Pct*200000)+MM_Cost_Flat) -> 1000 | E24: =C24-D24 -> 1500 | F24: =IF(C24>0,E24/C24,"") -> 0.6 | G24: Public price: 1% (no deal yet)
A25: in € | C25: =IF(ISNUMBER(C24),C24/FX_EUR,"") -> 3.8112254 | D25: =IF(ISNUMBER(D24),D24/FX_EUR,"") -> 1.5244902 | E25: =IF(ISNUMBER(E24),E24/FX_EUR,"") -> 2.2867353
A26: 1,000,000 FCFA to a wallet, above the free amount (both caps apply) | B26: Wave / Orange Money (or an aggregator) | C26: =MIN(MM_Fee*1000000,MM_Fee_Cap) -> 8500 | D26: =(IF(MM_Cost_Cap>0,MIN(MM_Cost_Pct*1000000,MM_Cost_Cap),MM_Cost_Pct*1000000)+MM_Cost_Flat) -> 2500 | E26: =C26-D26 -> 6000 | F26: =IF(C26>0,E26/C26,"") -> 0.70588235 | G26: 5,000 FCFA cap: secondary source, to verify
A27: in € | C27: =IF(ISNUMBER(C26),C26/FX_EUR,"") -> 12.958166 | D27: =IF(ISNUMBER(D26),D26/FX_EUR,"") -> 3.8112254 | E27: =IF(ISNUMBER(E26),E26/FX_EUR,"") -> 9.146941
A28: 100,000 FCFA collected by Wave through a payment link | B28: Wave / Orange Money (or an aggregator) | C28: =PL_Fee*100000 -> 1200 | D28: =PL_Cost*100000 -> 1000 | E28: =C28-D28 -> 200 | F28: =IF(C28>0,E28/C28,"") -> 0.16666667 | G28: Public price: about 1%
A29: in € | C29: =IF(ISNUMBER(C28),C28/FX_EUR,"") -> 1.8293882 | D29: =IF(ISNUMBER(D28),D28/FX_EUR,"") -> 1.5244902 | E29: =IF(ISNUMBER(E28),E28/FX_EUR,"") -> 0.30489803
A30: Cards
A31: Active card, one month | B31: Card processor | C31: =0 -> 0 | D31: =Card_Proc_Fee -> 600 | E31: =C31-D31 -> -600 | F31: =IF(C31>0,E31/C31,"") | G31: Estimate: processors quote privately
A32: in € | C32: =IF(ISNUMBER(C31),C31/FX_EUR,"") -> 0 | D32: =IF(ISNUMBER(D31),D31/FX_EUR,"") -> 0.9146941 | E32: =IF(ISNUMBER(E31),E31/FX_EUR,"") -> -0.9146941
A33: Extra physical card (one-off) | B33: Card printer | C33: =Card_Fee -> 6500 | D33: =Card_Prod_Cost -> 4500 | E33: =C33-D33 -> 2000 | F33: =IF(C33>0,E33/C33,"") -> 0.30769231 | G33: Researched: 3,000–6,000 FCFA
A34: in € | C34: =IF(ISNUMBER(C33),C33/FX_EUR,"") -> 9.9091861 | D34: =IF(ISNUMBER(D33),D33/FX_EUR,"") -> 6.8602058 | E34: =IF(ISNUMBER(E33),E33/FX_EUR,"") -> 3.0489803
A35: 50,000 FCFA card payment in FCFA | B35: Fraud and disputes (interchange stays with the bank) | C35: =0 -> 0 | D35: =50000*Fraud_Rate -> 75 | E35: =C35-D35 -> -75 | F35: =IF(C35>0,E35/C35,"") | G35: Estimate
A36: in € | C36: =IF(ISNUMBER(C35),C35/FX_EUR,"") -> 0 | D36: =IF(ISNUMBER(D35),D35/FX_EUR,"") -> 0.11433676 | E36: =IF(ISNUMBER(E35),E35/FX_EUR,"") -> -0.11433676
A37: 25,000 FCFA card payment in dollars (ads, software) | B37: Visa / Mastercard and the partner bank (FX margin) | C37: =25000*FX_Fee+FX_Fixed_Fee -> 950 | D37: =25000*(Scheme_Rate+Fraud_Rate)+Scheme_Fixed -> 587.5 | E37: =C37-D37 -> 362.5 | F37: =IF(C37>0,E37/C37,"") -> 0.38157895 | G37: Researched: network fees about 0.9% + $0.43; bank FX margin to quote
A38: in € | C38: =IF(ISNUMBER(C37),C37/FX_EUR,"") -> 1.4482657 | D38: =IF(ISNUMBER(D37),D37/FX_EUR,"") -> 0.89563798 | E38: =IF(ISNUMBER(E37),E37/FX_EUR,"") -> 0.55262769
A39: International payments and payroll
A40: 1,000,000 FCFA paid to a supplier abroad | B40: Partner bank or provider (Capi Money…) | C40: =1000000*Intl_Fee+Intl_Fixed_Fee -> 39500 | D40: =1000000*Intl_Cost -> 27000 | E40: =C40-D40 -> 12500 | F40: =IF(C40>0,E40/C40,"") -> 0.3164557 | G40: Assumed: provider not chosen yet
A41: in € | C41: =IF(ISNUMBER(C40),C40/FX_EUR,"") -> 60.217362 | D41: =IF(ISNUMBER(D40),D40/FX_EUR,"") -> 41.161235 | E41: =IF(ISNUMBER(E40),E40/FX_EUR,"") -> 19.056127
A42: One payslip with the monthly declarations | B42: WhatsApp / SMS, computing | C42: =Payslip_Fee -> 900 | D42: =Payslip_Cost -> 15 | E42: =C42-D42 -> 885 | F42: =IF(C42>0,E42/C42,"") -> 0.98333333 | G42: Researched
...

Sheet Hiring plan
A1: Hiring plan
A2: One line per hire or group of identical hires. Edit headcount, start month, end month (leave blank if they stay) and gross salary. Spare lines at the bottom for new roles.
A4: # | B4: Department | C4: Role | D4: Country | E4: Category | F4: Headcount | G4: Start month | H4: End month | I4: Gross salary (FCFA / month) | J4: Agency hire (Y/N) | K4: Employer cost per person (FCFA / month) | L4: Note | M4: Gross salary (€ / month) | N4: Employer cost per person (€ / month)
A5: 1 | B5: Leadership | C5: CEO (full salary from year 2) | D5: SN | F5: 1 | G5: 13 | I5: 2500000 | J5: Y | K5: =IF(I5="",0,I5*(1+Employer_Charges)) -> 3250000 | L5: Founders and shareholders run the company unpaid in year 1 (decision). | M5: =IF(N(I5)=0,0,I5/FX_EUR) -> 3811.2254 | N5: =IF(N(K5)=0,0,K5/FX_EUR) -> 4954.5931
A6: 2 | B6: Engineering & product | C6: CTO (also codes) | D6: SN | F6: 1 | G6: 1 | I6: 2500000 | J6: Y | K6: =IF(I6="",0,I6*(1+Employer_Charges)) -> 3250000 | L6: Developers are added with volume on the Staff sheet (2 at the start). | M6: =IF(N(I6)=0,0,I6/FX_EUR) -> 3811.2254 | N6: =IF(N(K6)=0,0,K6/FX_EUR) -> 4954.5931
A7: 3 | B7: Finance & admin | C7: Financial expert (finance, partners, credit lead) | D7: SN | F7: 1 | G7: 1 | I7: 1500000 | J7: Y | K7: =IF(I7="",0,I7*(1+Employer_Charges)) -> 1950000 | L7: Starting team. Credit analysts are added with the loan book. | M7: =IF(N(I7)=0,0,I7/FX_EUR) -> 2286.7353 | N7: =IF(N(K7)=0,0,K7/FX_EUR) -> 2972.7558
A8: 4 | B8: Sales & partnerships | C8: Sales lead (also sells; incl. bonus) | D8: SN | E8: Sales rep | F8: 1 | G8: 1 | I8: 1200000 | J8: N | K8: =IF(I8="",0,I8*(1+Employer_Charges)) -> 1560000 | L8: Plus 2 field reps from month 4, then reps grow with clients (Staff sheet). | M8: =IF(N(I8)=0,0,I8/FX_EUR) -> 1829.3882 | N8: =IF(N(K8)=0,0,K8/FX_EUR) -> 2378.2047
A9: 5 | B9: Marketing | C9: Marketing manager (senior) | D9: SN | F9: 1 | G9: 4 | I9: 900000 | J9: N | K9: =IF(I9="",0,I9*(1+Employer_Charges)) -> 1170000 | L9: Prepares the launch; runs digital ads and partnerships. | M9: =IF(N(I9)=0,0,I9/FX_EUR) -> 1372.0412 | N9: =IF(N(K9)=0,0,K9/FX_EUR) -> 1783.6535
A10: 6 | B10: Marketing | C10: Marketing officer (junior) | D10: SN | F10: 1 | G10: 5 | I10: 400000 | J10: N | K10: =IF(I10="",0,I10*(1+Employer_Charges)) -> 520000 | L10: Content, social media, events. | M10: =IF(N(I10)=0,0,I10/FX_EUR) -> 609.79607 | N10: =IF(N(K10)=0,0,K10/FX_EUR) -> 792.73489
A11: 7 | B11: Leadership | C11: Country manager, Abidjan | D11: CI | F11: 1 | G11: =CI_Office_Start -> 18 | I11: 2800000 | J11: Y | K11: =IF(I11="",0,I11*(1+Employer_Charges)) -> 3640000 | L11: Joins when the Abidjan office opens. | M11: =IF(N(I11)=0,0,I11/FX_EUR) -> 4268.5725 | N11: =IF(N(K11)=0,0,K11/FX_EUR) -> 5549.1442
A12: 8 | B12: Compliance & risk | C12: Compliance officer (AML/CFT) | D12: SN | F12: 1 | G12: =SFD_Acq_Month -> 24 | I12: 1500000 | J12: Y | K12: =IF(I12="",0,I12*(1+Employer_Charges)) -> 1950000 | L12: Required once Kelen holds its own licence (SFD). | M12: =IF(N(I12)=0,0,I12/FX_EUR) -> 2286.7353 | N12: =IF(N(K12)=0,0,K12/FX_EUR) -> 2972.7558
A13: 9 | K13: =IF(I13="",0,I13*(1+Employer_Charges)) -> 0 | M13: =IF(N(I13)=0,0,I13/FX_EUR) -> 0 | N13: =IF(N(K13)=0,0,K13/FX_EUR) -> 0
A14: 10 | K14: =IF(I14="",0,I14*(1+Employer_Charges)) -> 0 | M14: =IF(N(I14)=0,0,I14/FX_EUR) -> 0 | N14: =IF(N(K14)=0,0,K14/FX_EUR) -> 0
A15: 11 | K15: =IF(I15="",0,I15*(1+Employer_Charges)) -> 0 | M15: =IF(N(I15)=0,0,I15/FX_EUR) -> 0 | N15: =IF(N(K15)=0,0,K15/FX_EUR) -> 0
A16: 12 | K16: =IF(I16="",0,I16*(1+Employer_Charges)) -> 0 | M16: =IF(N(I16)=0,0,I16/FX_EUR) -> 0 | N16: =IF(N(K16)=0,0,K16/FX_EUR) -> 0
A17: 13 | K17: =IF(I17="",0,I17*(1+Employer_Charges)) -> 0 | M17: =IF(N(I17)=0,0,I17/FX_EUR) -> 0 | N17: =IF(N(K17)=0,0,K17/FX_EUR) -> 0
A18: 14 | K18: =IF(I18="",0,I18*(1+Employer_Charges)) -> 0 | M18: =IF(N(I18)=0,0,I18/FX_EUR) -> 0 | N18: =IF(N(K18)=0,0,K18/FX_EUR) -> 0
A19: 15 | K19: =IF(I19="",0,I19*(1+Employer_Charges)) -> 0 | M19: =IF(N(I19)=0,0,I19/FX_EUR) -> 0 | N19: =IF(N(K19)=0,0,K19/FX_EUR) -> 0
A20: 16 | K20: =IF(I20="",0,I20*(1+Employer_Charges)) -> 0 | M20: =IF(N(I20)=0,0,I20/FX_EUR) -> 0 | N20: =IF(N(K20)=0,0,K20/FX_EUR) -> 0
A21: 17 | K21: =IF(I21="",0,I21*(1+Employer_Charges)) -> 0 | M21: =IF(N(I21)=0,0,I21/FX_EUR) -> 0 | N21: =IF(N(K21)=0,0,K21/FX_EUR) -> 0
A22: 18 | K22: =IF(I22="",0,I22*(1+Employer_Charges)) -> 0 | M22: =IF(N(I22)=0,0,I22/FX_EUR) -> 0 | N22: =IF(N(K22)=0,0,K22/FX_EUR) -> 0
A23: 19 | K23: =IF(I23="",0,I23*(1+Employer_Charges)) -> 0 | M23: =IF(N(I23)=0,0,I23/FX_EUR) -> 0 | N23: =IF(N(K23)=0,0,K23/FX_EUR) -> 0
A24: 20 | K24: =IF(I24="",0,I24*(1+Employer_Charges)) -> 0 | M24: =IF(N(I24)=0,0,I24/FX_EUR) -> 0 | N24: =IF(N(K24)=0,0,K24/FX_EUR) -> 0
... A32: 28 | K32: =IF(I32="",0,I32*(1+Employer_Charges)) -> 0 | M32: =IF(N(I32)=0,0,I32/FX_EUR) -> 0 | N32: =IF(N(K32)=0,0,K32/FX_EUR) -> 0
B34: Employer cost = gross salary × (1 + employer charges), 30% on Assumptions section 8. Customer support, developers, field sales reps and credit analysts grow with volume: see the Staff sheet and the ratios on Assumptions section 8.

Sheet Staff
A1: Staff
A2: Headcount and employer cost by month, from the hiring plan. Pay rises each year by the rate on Assumptions.
A3: Month # | D3: Total / end | E3: 1 | F3: =E3+1 -> 2 | G3: =F3+1 -> 3 | H3: =G3+1 -> 4 | I3: =H3+1 -> 5 | J3: =I3+1 -> 6 | K3: =J3+1 -> 7 | L3: =K3+1 -> 8 | M3: =L3+1 -> 9 | ... BL3: =BK3+1 -> 60
A4: Month | E4: =DATE(YEAR(Start_Date),MONTH(Start_Date)+E3-1,1) -> 46388 | F4: =DATE(YEAR(Start_Date),MONTH(Start_Date)+F3-1,1) -> 46419 | G4: =DATE(YEAR(Start_Date),MONTH(Start_Date)+G3-1,1) -> 46447 | H4: =DATE(YEAR(Start_Date),MONTH(Start_Date)+H3-1,1) -> 46478 | I4: =DATE(YEAR(Start_Date),MONTH(Start_Date)+I3-1,1) -> 46508 | J4: =DATE(YEAR(Start_Date),MONTH(Start_Date)+J3-1,1) -> 46539 | K4: =DATE(YEAR(Start_Date),MONTH(Start_Date)+K3-1,1) -> 46569 | L4: =DATE(YEAR(Start_Date),MONTH(Start_Date)+L3-1,1) -> 46600 | ... BL4: =DATE(YEAR(Start_Date),MONTH(Start_Date)+BL3-1,1) -> 48183
A5: Year | E5: =INT((E3-1)/12)+1 -> 1 | F5: =INT((F3-1)/12)+1 -> 1 | G5: =INT((G3-1)/12)+1 -> 1 | H5: =INT((H3-1)/12)+1 -> 1 | I5: =INT((I3-1)/12)+1 -> 1 | J5: =INT((J3-1)/12)+1 -> 1 | K5: =INT((K3-1)/12)+1 -> 1 | L5: =INT((L3-1)/12)+1 -> 1 | ... BL5: =INT((BL3-1)/12)+1 -> 5
A8: Headcount by hire line
A9: =IF('Hiring plan'!$C$5="","(spare line 1)",'Hiring plan'!$C$5&" · "&'Hiring plan'!$D$5) -> CEO (full salary from year 2) · SN | B9: people | D9: =MAX(E9:BL9) -> 1 | E9: =IF(AND(N('Hiring plan'!$F$5)>0,E$3>='Hiring plan'!$G$5,E$3<=IF('Hiring plan'!$H$5="",999,'Hiring plan'!$H$5)),'Hiring plan'!$F$5,0) -> 0 | F9: =IF(AND(N('Hiring plan'!$F$5)>0,F$3>='Hiring plan'!$G$5,F$3<=IF('Hiring plan'!$H$5="",999,'Hiring plan'!$H$5)),'Hiring plan'!$F$5,0) -> 0 | G9: =IF(AND(N('Hiring plan'!$F$5)>0,G$3>='Hiring plan'!$G$5,G$3<=IF('Hiring plan'!$H$5="",999,'Hiring plan'!$H$5)),'Hiring plan'!$F$5,0) -> 0 | H9: =IF(AND(N('Hiring plan'!$F$5)>0,H$3>='Hiring plan'!$G$5,H$3<=IF('Hiring plan'!$H$5="",999,'Hiring plan'!$H$5)),'Hiring plan'!$F$5,0) -> 0 | I9: =IF(AND(N('Hiring plan'!$F$5)>0,I$3>='Hiring plan'!$G$5,I$3<=IF('Hiring plan'!$H$5="",999,'Hiring plan'!$H$5)),'Hiring plan'!$F$5,0) -> 0 | J9: =IF(AND(N('Hiring plan'!$F$5)>0,J$3>='Hiring plan'!$G$5,J$3<=IF('Hiring plan'!$H$5="",999,'Hiring plan'!$H$5)),'Hiring plan'!$F$5,0) -> 0 | K9: =IF(AND(N('Hiring plan'!$F$5)>0,K$3>='Hiring plan'!$G$5,K$3<=IF('Hiring plan'!$H$5="",999,'Hiring plan'!$H$5)),'Hiring plan'!$F$5,0) -> 0 | L9: =IF(AND(N('Hiring plan'!$F$5)>0,L$3>='Hiring plan'!$G$5,L$3<=IF('Hiring plan'!$H$5="",999,'Hiring plan'!$H$5)),'Hiring plan'!$F$5,0) -> 0 | ... BL9: =IF(AND(N('Hiring plan'!$F$5)>0,BL$3>='Hiring plan'!$G$5,BL$3<=IF('Hiring plan'!$H$5="",999,'Hiring plan'!$H$5)),'Hiring plan'!$F$5,0) -> 1
A10: =IF('Hiring plan'!$C$6="","(spare line 2)",'Hiring plan'!$C$6&" · "&'Hiring plan'!$D$6) -> CTO (also codes) · SN | B10: people | D10: =MAX(E10:BL10) -> 1 | E10: =IF(AND(N('Hiring plan'!$F$6)>0,E$3>='Hiring plan'!$G$6,E$3<=IF('Hiring plan'!$H$6="",999,'Hiring plan'!$H$6)),'Hiring plan'!$F$6,0) -> 1 | F10: =IF(AND(N('Hiring plan'!$F$6)>0,F$3>='Hiring plan'!$G$6,F$3<=IF('Hiring plan'!$H$6="",999,'Hiring plan'!$H$6)),'Hiring plan'!$F$6,0) -> 1 | G10: =IF(AND(N('Hiring plan'!$F$6)>0,G$3>='Hiring plan'!$G$6,G$3<=IF('Hiring plan'!$H$6="",999,'Hiring plan'!$H$6)),'Hiring plan'!$F$6,0) -> 1 | H10: =IF(AND(N('Hiring plan'!$F$6)>0,H$3>='Hiring plan'!$G$6,H$3<=IF('Hiring plan'!$H$6="",999,'Hiring plan'!$H$6)),'Hiring plan'!$F$6,0) -> 1 | I10: =IF(AND(N('Hiring plan'!$F$6)>0,I$3>='Hiring plan'!$G$6,I$3<=IF('Hiring plan'!$H$6="",999,'Hiring plan'!$H$6)),'Hiring plan'!$F$6,0) -> 1 | J10: =IF(AND(N('Hiring plan'!$F$6)>0,J$3>='Hiring plan'!$G$6,J$3<=IF('Hiring plan'!$H$6="",999,'Hiring plan'!$H$6)),'Hiring plan'!$F$6,0) -> 1 | K10: =IF(AND(N('Hiring plan'!$F$6)>0,K$3>='Hiring plan'!$G$6,K$3<=IF('Hiring plan'!$H$6="",999,'Hiring plan'!$H$6)),'Hiring plan'!$F$6,0) -> 1 | L10: =IF(AND(N('Hiring plan'!$F$6)>0,L$3>='Hiring plan'!$G$6,L$3<=IF('Hiring plan'!$H$6="",999,'Hiring plan'!$H$6)),'Hiring plan'!$F$6,0) -> 1 | ... BL10: =IF(AND(N('Hiring plan'!$F$6)>0,BL$3>='Hiring plan'!$G$6,BL$3<=IF('Hiring plan'!$H$6="",999,'Hiring plan'!$H$6)),'Hiring plan'!$F$6,0) -> 1
A11: =IF('Hiring plan'!$C$7="","(spare line 3)",'Hiring plan'!$C$7&" · "&'Hiring plan'!$D$7) -> Financial expert (finance, partners, credit lead) · SN | B11: people | D11: =MAX(E11:BL11) -> 1 | E11: =IF(AND(N('Hiring plan'!$F$7)>0,E$3>='Hiring plan'!$G$7,E$3<=IF('Hiring plan'!$H$7="",999,'Hiring plan'!$H$7)),'Hiring plan'!$F$7,0) -> 1 | F11: =IF(AND(N('Hiring plan'!$F$7)>0,F$3>='Hiring plan'!$G$7,F$3<=IF('Hiring plan'!$H$7="",999,'Hiring plan'!$H$7)),'Hiring plan'!$F$7,0) -> 1 | G11: =IF(AND(N('Hiring plan'!$F$7)>0,G$3>='Hiring plan'!$G$7,G$3<=IF('Hiring plan'!$H$7="",999,'Hiring plan'!$H$7)),'Hiring plan'!$F$7,0) -> 1 | H11: =IF(AND(N('Hiring plan'!$F$7)>0,H$3>='Hiring plan'!$G$7,H$3<=IF('Hiring plan'!$H$7="",999,'Hiring plan'!$H$7)),'Hiring plan'!$F$7,0) -> 1 | I11: =IF(AND(N('Hiring plan'!$F$7)>0,I$3>='Hiring plan'!$G$7,I$3<=IF('Hiring plan'!$H$7="",999,'Hiring plan'!$H$7)),'Hiring plan'!$F$7,0) -> 1 | J11: =IF(AND(N('Hiring plan'!$F$7)>0,J$3>='Hiring plan'!$G$7,J$3<=IF('Hiring plan'!$H$7="",999,'Hiring plan'!$H$7)),'Hiring plan'!$F$7,0) -> 1 | K11: =IF(AND(N('Hiring plan'!$F$7)>0,K$3>='Hiring plan'!$G$7,K$3<=IF('Hiring plan'!$H$7="",999,'Hiring plan'!$H$7)),'Hiring plan'!$F$7,0) -> 1 | L11: =IF(AND(N('Hiring plan'!$F$7)>0,L$3>='Hiring plan'!$G$7,L$3<=IF('Hiring plan'!$H$7="",999,'Hiring plan'!$H$7)),'Hiring plan'!$F$7,0) -> 1 | ... BL11: =IF(AND(N('Hiring plan'!$F$7)>0,BL$3>='Hiring plan'!$G$7,BL$3<=IF('Hiring plan'!$H$7="",999,'Hiring plan'!$H$7)),'Hiring plan'!$F$7,0) -> 1
A12: =IF('Hiring plan'!$C$8="","(spare line 4)",'Hiring plan'!$C$8&" · "&'Hiring plan'!$D$8) -> Sales lead (also sells; incl. bonus) · SN | B12: people | D12: =MAX(E12:BL12) -> 1 | E12: =IF(AND(N('Hiring plan'!$F$8)>0,E$3>='Hiring plan'!$G$8,E$3<=IF('Hiring plan'!$H$8="",999,'Hiring plan'!$H$8)),'Hiring plan'!$F$8,0) -> 1 | F12: =IF(AND(N('Hiring plan'!$F$8)>0,F$3>='Hiring plan'!$G$8,F$3<=IF('Hiring plan'!$H$8="",999,'Hiring plan'!$H$8)),'Hiring plan'!$F$8,0) -> 1 | G12: =IF(AND(N('Hiring plan'!$F$8)>0,G$3>='Hiring plan'!$G$8,G$3<=IF('Hiring plan'!$H$8="",999,'Hiring plan'!$H$8)),'Hiring plan'!$F$8,0) -> 1 | H12: =IF(AND(N('Hiring plan'!$F$8)>0,H$3>='Hiring plan'!$G$8,H$3<=IF('Hiring plan'!$H$8="",999,'Hiring plan'!$H$8)),'Hiring plan'!$F$8,0) -> 1 | I12: =IF(AND(N('Hiring plan'!$F$8)>0,I$3>='Hiring plan'!$G$8,I$3<=IF('Hiring plan'!$H$8="",999,'Hiring plan'!$H$8)),'Hiring plan'!$F$8,0) -> 1 | J12: =IF(AND(N('Hiring plan'!$F$8)>0,J$3>='Hiring plan'!$G$8,J$3<=IF('Hiring plan'!$H$8="",999,'Hiring plan'!$H$8)),'Hiring plan'!$F$8,0) -> 1 | K12: =IF(AND(N('Hiring plan'!$F$8)>0,K$3>='Hiring plan'!$G$8,K$3<=IF('Hiring plan'!$H$8="",999,'Hiring plan'!$H$8)),'Hiring plan'!$F$8,0) -> 1 | L12: =IF(AND(N('Hiring plan'!$F$8)>0,L$3>='Hiring plan'!$G$8,L$3<=IF('Hiring plan'!$H$8="",999,'Hiring plan'!$H$8)),'Hiring plan'!$F$8,0) -> 1 | ... BL12: =IF(AND(N('Hiring plan'!$F$8)>0,BL$3>='Hiring plan'!$G$8,BL$3<=IF('Hiring plan'!$H$8="",999,'Hiring plan'!$H$8)),'Hiring plan'!$F$8,0) -> 1
A13: =IF('Hiring plan'!$C$9="","(spare line 5)",'Hiring plan'!$C$9&" · "&'Hiring plan'!$D$9) -> Marketing manager (senior) · SN | B13: people | D13: =MAX(E13:BL13) -> 1 | E13: =IF(AND(N('Hiring plan'!$F$9)>0,E$3>='Hiring plan'!$G$9,E$3<=IF('Hiring plan'!$H$9="",999,'Hiring plan'!$H$9)),'Hiring plan'!$F$9,0) -> 0 | F13: =IF(AND(N('Hiring plan'!$F$9)>0,F$3>='Hiring plan'!$G$9,F$3<=IF('Hiring plan'!$H$9="",999,'Hiring plan'!$H$9)),'Hiring plan'!$F$9,0) -> 0 | G13: =IF(AND(N('Hiring plan'!$F$9)>0,G$3>='Hiring plan'!$G$9,G$3<=IF('Hiring plan'!$H$9="",999,'Hiring plan'!$H$9)),'Hiring plan'!$F$9,0) -> 0 | H13: =IF(AND(N('Hiring plan'!$F$9)>0,H$3>='Hiring plan'!$G$9,H$3<=IF('Hiring plan'!$H$9="",999,'Hiring plan'!$H$9)),'Hiring plan'!$F$9,0) -> 1 | I13: =IF(AND(N('Hiring plan'!$F$9)>0,I$3>='Hiring plan'!$G$9,I$3<=IF('Hiring plan'!$H$9="",999,'Hiring plan'!$H$9)),'Hiring plan'!$F$9,0) -> 1 | J13: =IF(AND(N('Hiring plan'!$F$9)>0,J$3>='Hiring plan'!$G$9,J$3<=IF('Hiring plan'!$H$9="",999,'Hiring plan'!$H$9)),'Hiring plan'!$F$9,0) -> 1 | K13: =IF(AND(N('Hiring plan'!$F$9)>0,K$3>='Hiring plan'!$G$9,K$3<=IF('Hiring plan'!$H$9="",999,'Hiring plan'!$H$9)),'Hiring plan'!$F$9,0) -> 1 | L13: =IF(AND(N('Hiring plan'!$F$9)>0,L$3>='Hiring plan'!$G$9,L$3<=IF('Hiring plan'!$H$9="",999,'Hiring plan'!$H$9)),'Hiring plan'!$F$9,0) -> 1 | ... BL13: =IF(AND(N('Hiring plan'!$F$9)>0,BL$3>='Hiring plan'!$G$9,BL$3<=IF('Hiring plan'!$H$9="",999,'Hiring plan'!$H$9)),'Hiring plan'!$F$9,0) -> 1
A14: =IF('Hiring plan'!$C$10="","(spare line 6)",'Hiring plan'!$C$10&" · "&'Hiring plan'!$D$10) -> Marketing officer (junior) · SN | B14: people | D14: =MAX(E14:BL14) -> 1 | E14: =IF(AND(N('Hiring plan'!$F$10)>0,E$3>='Hiring plan'!$G$10,E$3<=IF('Hiring plan'!$H$10="",999,'Hiring plan'!$H$10)),'Hiring plan'!$F$10,0) -> 0 | F14: =IF(AND(N('Hiring plan'!$F$10)>0,F$3>='Hiring plan'!$G$10,F$3<=IF('Hiring plan'!$H$10="",999,'Hiring plan'!$H$10)),'Hiring plan'!$F$10,0) -> 0 | G14: =IF(AND(N('Hiring plan'!$F$10)>0,G$3>='Hiring plan'!$G$10,G$3<=IF('Hiring plan'!$H$10="",999,'Hiring plan'!$H$10)),'Hiring plan'!$F$10,0) -> 0 | H14: =IF(AND(N('Hiring plan'!$F$10)>0,H$3>='Hiring plan'!$G$10,H$3<=IF('Hiring plan'!$H$10="",999,'Hiring plan'!$H$10)),'Hiring plan'!$F$10,0) -> 0 | I14: =IF(AND(N('Hiring plan'!$F$10)>0,I$3>='Hiring plan'!$G$10,I$3<=IF('Hiring plan'!$H$10="",999,'Hiring plan'!$H$10)),'Hiring plan'!$F$10,0) -> 1 | J14: =IF(AND(N('Hiring plan'!$F$10)>0,J$3>='Hiring plan'!$G$10,J$3<=IF('Hiring plan'!$H$10="",999,'Hiring plan'!$H$10)),'Hiring plan'!$F$10,0) -> 1 | K14: =IF(AND(N('Hiring plan'!$F$10)>0,K$3>='Hiring plan'!$G$10,K$3<=IF('Hiring plan'!$H$10="",999,'Hiring plan'!$H$10)),'Hiring plan'!$F$10,0) -> 1 | L14: =IF(AND(N('Hiring plan'!$F$10)>0,L$3>='Hiring plan'!$G$10,L$3<=IF('Hiring plan'!$H$10="",999,'Hiring plan'!$H$10)),'Hiring plan'!$F$10,0) -> 1 | ... BL14: =IF(AND(N('Hiring plan'!$F$10)>0,BL$3>='Hiring plan'!$G$10,BL$3<=IF('Hiring plan'!$H$10="",999,'Hiring plan'!$H$10)),'Hiring plan'!$F$10,0) -> 1
A15: =IF('Hiring plan'!$C$11="","(spare line 7)",'Hiring plan'!$C$11&" · "&'Hiring plan'!$D$11) -> Country manager, Abidjan · CI | B15: people | D15: =MAX(E15:BL15) -> 1 | E15: =IF(AND(N('Hiring plan'!$F$11)>0,E$3>='Hiring plan'!$G$11,E$3<=IF('Hiring plan'!$H$11="",999,'Hiring plan'!$H$11)),'Hiring plan'!$F$11,0) -> 0 | F15: =IF(AND(N('Hiring plan'!$F$11)>0,F$3>='Hiring plan'!$G$11,F$3<=IF('Hiring plan'!$H$11="",999,'Hiring plan'!$H$11)),'Hiring plan'!$F$11,0) -> 0 | G15: =IF(AND(N('Hiring plan'!$F$11)>0,G$3>='Hiring plan'!$G$11,G$3<=IF('Hiring plan'!$H$11="",999,'Hiring plan'!$H$11)),'Hiring plan'!$F$11,0) -> 0 | H15: =IF(AND(N('Hiring plan'!$F$11)>0,H$3>='Hiring plan'!$G$11,H$3<=IF('Hiring plan'!$H$11="",999,'Hiring plan'!$H$11)),'Hiring plan'!$F$11,0) -> 0 | I15: =IF(AND(N('Hiring plan'!$F$11)>0,I$3>='Hiring plan'!$G$11,I$3<=IF('Hiring plan'!$H$11="",999,'Hiring plan'!$H$11)),'Hiring plan'!$F$11,0) -> 0 | J15: =IF(AND(N('Hiring plan'!$F$11)>0,J$3>='Hiring plan'!$G$11,J$3<=IF('Hiring plan'!$H$11="",999,'Hiring plan'!$H$11)),'Hiring plan'!$F$11,0) -> 0 | K15: =IF(AND(N('Hiring plan'!$F$11)>0,K$3>='Hiring plan'!$G$11,K$3<=IF('Hiring plan'!$H$11="",999,'Hiring plan'!$H$11)),'Hiring plan'!$F$11,0) -> 0 | L15: =IF(AND(N('Hiring plan'!$F$11)>0,L$3>='Hiring plan'!$G$11,L$3<=IF('Hiring plan'!$H$11="",999,'Hiring plan'!$H$11)),'Hiring plan'!$F$11,0) -> 0 | ... BL15: =IF(AND(N('Hiring plan'!$F$11)>0,BL$3>='Hiring plan'!$G$11,BL$3<=IF('Hiring plan'!$H$11="",999,'Hiring plan'!$H$11)),'Hiring plan'!$F$11,0) -> 1
A16: =IF('Hiring plan'!$C$12="","(spare line 8)",'Hiring plan'!$C$12&" · "&'Hiring plan'!$D$12) -> Compliance officer (AML/CFT) · SN | B16: people | D16: =MAX(E16:BL16) -> 1 | E16: =IF(AND(N('Hiring plan'!$F$12)>0,E$3>='Hiring plan'!$G$12,E$3<=IF('Hiring plan'!$H$12="",999,'Hiring plan'!$H$12)),'Hiring plan'!$F$12,0) -> 0 | F16: =IF(AND(N('Hiring plan'!$F$12)>0,F$3>='Hiring plan'!$G$12,F$3<=IF('Hiring plan'!$H$12="",999,'Hiring plan'!$H$12)),'Hiring plan'!$F$12,0) -> 0 | G16: =IF(AND(N('Hiring plan'!$F$12)>0,G$3>='Hiring plan'!$G$12,G$3<=IF('Hiring plan'!$H$12="",999,'Hiring plan'!$H$12)),'Hiring plan'!$F$12,0) -> 0 | H16: =IF(AND(N('Hiring plan'!$F$12)>0,H$3>='Hiring plan'!$G$12,H$3<=IF('Hiring plan'!$H$12="",999,'Hiring plan'!$H$12)),'Hiring plan'!$F$12,0) -> 0 | I16: =IF(AND(N('Hiring plan'!$F$12)>0,I$3>='Hiring plan'!$G$12,I$3<=IF('Hiring plan'!$H$12="",999,'Hiring plan'!$H$12)),'Hiring plan'!$F$12,0) -> 0 | J16: =IF(AND(N('Hiring plan'!$F$12)>0,J$3>='Hiring plan'!$G$12,J$3<=IF('Hiring plan'!$H$12="",999,'Hiring plan'!$H$12)),'Hiring plan'!$F$12,0) -> 0 | K16: =IF(AND(N('Hiring plan'!$F$12)>0,K$3>='Hiring plan'!$G$12,K$3<=IF('Hiring plan'!$H$12="",999,'Hiring plan'!$H$12)),'Hiring plan'!$F$12,0) -> 0 | L16: =IF(AND(N('Hiring plan'!$F$12)>0,L$3>='Hiring plan'!$G$12,L$3<=IF('Hiring plan'!$H$12="",999,'Hiring plan'!$H$12)),'Hiring plan'!$F$12,0) -> 0 | ... BL16: =IF(AND(N('Hiring plan'!$F$12)>0,BL$3>='Hiring plan'!$G$12,BL$3<=IF('Hiring plan'!$H$12="",999,'Hiring plan'!$H$12)),'Hiring plan'!$F$12,0) -> 1
A17: =IF('Hiring plan'!$C$13="","(spare line 9)",'Hiring plan'!$C$13&" · "&'Hiring plan'!$D$13) -> (spare line 9) | B17: people | D17: =MAX(E17:BL17) -> 0 | E17: =IF(AND(N('Hiring plan'!$F$13)>0,E$3>='Hiring plan'!$G$13,E$3<=IF('Hiring plan'!$H$13="",999,'Hiring plan'!$H$13)),'Hiring plan'!$F$13,0) -> 0 | F17: =IF(AND(N('Hiring plan'!$F$13)>0,F$3>='Hiring plan'!$G$13,F$3<=IF('Hiring plan'!$H$13="",999,'Hiring plan'!$H$13)),'Hiring plan'!$F$13,0) -> 0 | G17: =IF(AND(N('Hiring plan'!$F$13)>0,G$3>='Hiring plan'!$G$13,G$3<=IF('Hiring plan'!$H$13="",999,'Hiring plan'!$H$13)),'Hiring plan'!$F$13,0) -> 0 | H17: =IF(AND(N('Hiring plan'!$F$13)>0,H$3>='Hiring plan'!$G$13,H$3<=IF('Hiring plan'!$H$13="",999,'Hiring plan'!$H$13)),'Hiring plan'!$F$13,0) -> 0 | I17: =IF(AND(N('Hiring plan'!$F$13)>0,I$3>='Hiring plan'!$G$13,I$3<=IF('Hiring plan'!$H$13="",999,'Hiring plan'!$H$13)),'Hiring plan'!$F$13,0) -> 0 | J17: =IF(AND(N('Hiring plan'!$F$13)>0,J$3>='Hiring plan'!$G$13,J$3<=IF('Hiring plan'!$H$13="",999,'Hiring plan'!$H$13)),'Hiring plan'!$F$13,0) -> 0 | K17: =IF(AND(N('Hiring plan'!$F$13)>0,K$3>='Hiring plan'!$G$13,K$3<=IF('Hiring plan'!$H$13="",999,'Hiring plan'!$H$13)),'Hiring plan'!$F$13,0) -> 0 | L17: =IF(AND(N('Hiring plan'!$F$13)>0,L$3>='Hiring plan'!$G$13,L$3<=IF('Hiring plan'!$H$13="",999,'Hiring plan'!$H$13)),'Hiring plan'!$F$13,0) -> 0 | ... BL17: =IF(AND(N('Hiring plan'!$F$13)>0,BL$3>='Hiring plan'!$G$13,BL$3<=IF('Hiring plan'!$H$13="",999,'Hiring plan'!$H$13)),'Hiring plan'!$F$13,0) -> 0
