Workbook

Sheet Cover
B2: Tabax (working name): business plan model
B3: B2B neobank for SMEs in Senegal, then Côte d'Ivoire. Five years, monthly, every figure driven by formulas.
B5: How to use
B6: 1. Pick a scenario | C6: Assumptions › cell D4: 1 = Prudent, 2 = Base, 3 = Ambitious. Rows with three values switch with it.
B7: 2. Change any input | C7: Inputs are blue on a cream background (Assumptions, Hiring plan, Market). Everything else is a formula: do not type over it.
B8: 3. Change the team | C8: Hiring plan: the fixed roles (founder, CTO, financial expert, sales lead, marketing, country manager, compliance officer). Support, developers, field sales reps and credit analysts grow with clients and the loan book: ratios on Assumptions, section 8.
B9: 4. Check the cash | C9: Dashboard › checks. If cash goes negative, raise more or earlier (Assumptions, section 11).
B11: Tabs
B12: Dashboard | C12: Headline numbers, year-by-year summary and checks.
B13: Assumptions | C13: Every hypothesis with its source: timing, acquisition, pricing, usage per client, cost to serve, credit, team and tools, Maak, fixed costs by year, funding.
B14: Unit costs | C14: What one of each thing costs or earns: one employee by role, one client by plan, one loan, and the price of every fixed item.
B15: Hiring plan | C15: Fixed roles, start months and salaries (employer cost = gross + 30% charges); 'Agency hire' adds the €800 agency fee.
B16: Staff | C16: Headcount and employer cost by month: fixed roles plus the team that grows with volume.
B17: Sales & marketing | C17: New clients by channel (field sales, partners, digital) and country; marketing budget; cost to acquire a client.
B18: Clients & revenue | C18: Active clients by plan, usage (cards, balances, payroll, payouts) and every non-credit revenue line.
B19: Credit | C19: Loan book by product, interest, cost of funds, losses and the share kept by Tabax; cash tied up by credit.
B20: Costs | C20: Variable costs, fixed costs by category and the contingency, month by month.
B21: P&L monthly | C21: Revenue, cost of revenue, gross margin, operating expenses, EBITDA, tax, net income (no depreciation: equipment is expensed).
B22: P&L annual | C22: Years 1–5, cash and funding, operating figures and a euro view.
B23: Cash flow | C23: Monthly cash, cash set aside, funding rounds, runway.
... B27: Regulatory path | C27: What each stage requires from regulators, and where its cost sits in the model.
B29: Colour code
B30: Blue on cream | C30: Input: change freely.
B31: Black | C31: Formula on the same sheet.
B32: Green | C32: Link to another sheet.
B34: Main caveats
B35: Estimates to replace | C35: Partner bank fees, card processor fees and minimums, interchange, the deposit income share, the changes to Maak's platform, the SFD acquisition price and running costs, insurance and the cost of wallet payouts have no public price. Replace them with term sheets and quotes.
B36: Taxes | C36: Amounts exclude VAT and the 17% tax on financial activities (TAF), which apply to fees. Corporate tax is simplified (30%, losses carried forward without limit).
B37: Côte d'Ivoire | C37: Same 30% employer charges as Senegal; the number of formal employers is an estimate.
B38: Credit | C38: No loans before month 18. A partner microfinance institution (SFD) lends at 23% a year, under the 24% SFD usury cap. Tabax buys an SFD around month 24 and lends from it in Senegal; Côte d'Ivoire loans stay with a partner. The loan book is funded by debt lines, not equity.
B39: Licences | C39: Tabax holds no licence of its own until the SFD acquisition: partners hold the accounts, cards and loans. See Regulatory path.
B40: Sources | C40: Business model v2, Cost breakdown in euros, Senegal launch plan and the research notes in this project, plus IPRES/ANSD 2024 and CEPICI 2025 for the market.

Sheet Dashboard
A1: Tabax business plan: dashboard
A2: Key results for the scenario selected on Assumptions. FCFA in columns B–H, euros in column D (headline) and J–N (year by year).
A4: Scenario | B4: =Assumptions!E4 -> Base
A6: Headline numbers
A7: First month with positive EBITDA | B7: =IF(MIN('P&L monthly'!E46:BL46)=999,"not reached",MIN('P&L monthly'!E46:BL46)) -> 41 | C7: month #
A8: which is | B8: =IF(ISNUMBER(B7),DATE(YEAR(Start_Date),MONTH(Start_Date)+B7-1,1),"-") -> 47604
A9: Peak funding need (lowest cumulative cash flow before funding) | B9: =-MIN(0,MIN('Cash flow'!E16:BL16)) -> 2.6598608e+09 | C9: FCFA
A10: in euros | B10: =B9/FX_EUR -> 4054931.6 | C10: €
A11: Equity raised in the plan | B11: =SUM('Cash flow'!E19:BL19) -> 3300000000 | C11: FCFA
A12: in euros | B12: =B11/FX_EUR -> 5030817.6 | C12: €
A13: Lowest closing cash | B13: =MIN('Cash flow'!E24:BL24) -> 3.2416017e+08 | C13: FCFA | D13: =B13/FX_EUR -> 494178.99 | E13: =IF(B13<0,"Cash goes negative: raise more or earlier (Assumptions, section 11)","OK: cash stays positive") -> OK: cash stays positive
A14: in month | B14: =MATCH(B13,'Cash flow'!E24:BL24,0) -> 14 | C14: month #
A15: Cash at the end of year 5 | B15: ='Cash flow'!BL24 -> 1.0956296e+09 | C15: FCFA | D15: =B15/FX_EUR -> 1670276.6
A16: Technology from Maak | B16: =IF(Maak_Option=1,"Lease (option 1)","Equity stake (option 2)") -> Lease (option 1)
A17: Maak's stake in Tabax | B17: =IF(Maak_Option=2,Maak_Equity_Pct,0) -> 0
A18: Year by year
A19: Year | D19: ='P&L annual'!D5 -> 2027 | E19: ='P&L annual'!E5 -> 2028 | F19: ='P&L annual'!F5 -> 2029 | G19: ='P&L annual'!G5 -> 2030 | H19: ='P&L annual'!H5 -> 2031 | J19: ="Y"&1&" (€)" -> Y1 (€) | K19: ="Y"&2&" (€)" -> Y2 (€) | L19: ="Y"&3&" (€)" -> Y3 (€) | M19: ="Y"&4&" (€)" -> Y4 (€) | N19: ="Y"&5&" (€)" -> Y5 (€)
A20: Active clients (end of year) | B20: clients | D20: ='P&L annual'!D50 -> 452.49288 | E20: ='P&L annual'!E50 -> 1644.6901 | F20: ='P&L annual'!F50 -> 3851.8996 | G20: ='P&L annual'!G50 -> 6994.9191 | H20: ='P&L annual'!H50 -> 10979.379
A21: New clients in the year | B21: clients | D21: ='P&L annual'!D53 -> 478.70801 | E21: ='P&L annual'!E53 -> 1372.7331 | F21: ='P&L annual'!F53 -> 2719.2239 | G21: ='P&L annual'!G53 -> 4165.4261 | H21: ='P&L annual'!H53 -> 5687.6227
A22: Headcount (end of year) | B22: people | D22: ='P&L annual'!D54 -> 11 | E22: ='P&L annual'!E54 -> 21 | F22: ='P&L annual'!F54 -> 36 | G22: ='P&L annual'!G54 -> 58 | H22: ='P&L annual'!H54 -> 84
A23: Total revenue | B23: FCFA | D23: ='P&L annual'!D17 -> 70060612 | E23: ='P&L annual'!E17 -> 5.1643063e+08 | F23: ='P&L annual'!F17 -> 1.7403131e+09 | G23: ='P&L annual'!G17 -> 3.6217766e+09 | H23: ='P&L annual'!H17 -> 6.1181572e+09 | J23: =D23/FX_EUR -> 106806.71 | K23: =E23/FX_EUR -> 787293.43 | L23: =F23/FX_EUR -> 2653090.3 | M23: =G23/FX_EUR -> 5521362.9 | N23: =H23/FX_EUR -> 9327070.5
A24: Gross margin | B24: FCFA | D24: ='P&L annual'!D26 -> 10591371 | E24: ='P&L annual'!E26 -> 1.6713033e+08 | F24: ='P&L annual'!F26 -> 6.7288491e+08 | G24: ='P&L annual'!G26 -> 1.5067646e+09 | H24: ='P&L annual'!H26 -> 2.6022451e+09 | J24: =D24/FX_EUR -> 16146.441 | K24: =E24/FX_EUR -> 254788.54 | L24: =F24/FX_EUR -> 1025806.4 | M24: =G24/FX_EUR -> 2297047.8 | N24: =H24/FX_EUR -> 3967097.1
A25: Gross margin % | B25: % | D25: ='P&L annual'!D27 -> 0.1511744 | E25: ='P&L annual'!E27 -> 0.3236259 | F25: ='P&L annual'!F27 -> 0.38664588 | G25: ='P&L annual'!G27 -> 0.41602912 | H25: ='P&L annual'!H27 -> 0.42533152
A26: Total operating expenses | B26: FCFA | D26: ='P&L annual'!D38 -> 4.4346828e+08 | E26: ='P&L annual'!E38 -> 6.8979512e+08 | F26: ='P&L annual'!F38 -> 1.0183646e+09 | G26: ='P&L annual'!G38 -> 1.3398265e+09 | H26: ='P&L annual'!H38 -> 1.7255357e+09 | J26: =D26/FX_EUR -> 676063.03 | K26: =E26/FX_EUR -> 1051585.9 | L26: =F26/FX_EUR -> 1552486.8 | M26: =G26/FX_EUR -> 2042552.4 | N26: =H26/FX_EUR -> 2630562.2
A27: EBITDA | B27: FCFA | D27: ='P&L annual'!D39 -> -4.3287691e+08 | E27: ='P&L annual'!E39 -> -5.2266479e+08 | F27: ='P&L annual'!F39 -> -3.4547966e+08 | G27: ='P&L annual'!G39 -> 1.6693801e+08 | H27: ='P&L annual'!H39 -> 8.7670939e+08 | J27: =D27/FX_EUR -> -659916.59 | K27: =E27/FX_EUR -> -796797.34 | L27: =F27/FX_EUR -> -526680.34 | M27: =G27/FX_EUR -> 254495.36 | N27: =H27/FX_EUR -> 1336534.8
A28: EBITDA margin | B28: % | D28: ='P&L annual'!D40 -> -6.1786058 | E28: ='P&L annual'!E40 -> -1.0120716 | F28: ='P&L annual'!F40 -> -0.1985158 | G28: ='P&L annual'!G40 -> 0.046092852 | H28: ='P&L annual'!H40 -> 0.14329632
A29: Net income | B29: FCFA | D29: ='P&L annual'!D42 -> -4.3287691e+08 | E29: ='P&L annual'!E42 -> -5.2266479e+08 | F29: ='P&L annual'!F42 -> -3.4547966e+08 | G29: ='P&L annual'!G42 -> 1.6693801e+08 | H29: ='P&L annual'!H42 -> 8.7670939e+08 | J29: =D29/FX_EUR -> -659916.59 | K29: =E29/FX_EUR -> -796797.34 | L29: =F29/FX_EUR -> -526680.34 | M29: =G29/FX_EUR -> 254495.36 | N29: =H29/FX_EUR -> 1336534.8
A30: Closing cash | B30: FCFA | D30: ='P&L annual'!D47 -> 4.0712309e+08 | E30: ='P&L annual'!E47 -> 1.5808688e+09 | F30: ='P&L annual'!F47 -> 8.687281e+08 | G30: ='P&L annual'!G47 -> 6.5909492e+08 | H30: ='P&L annual'!H47 -> 1.0956296e+09 | J30: =D30/FX_EUR -> 620655.15 | K30: =E30/FX_EUR -> 2410019 | L30: =F30/FX_EUR -> 1324367.4 | M30: =G30/FX_EUR -> 1004783.7 | N30: =H30/FX_EUR -> 1670276.6
A31: Loan book (end of year) | B31: FCFA | D31: ='P&L annual'!D55 -> 0 | E31: ='P&L annual'!E55 -> 5.3589485e+08 | F31: ='P&L annual'!F55 -> 3.0451853e+09 | G31: ='P&L annual'!G55 -> 5.8353417e+09 | H31: ='P&L annual'!H55 -> 9.163571e+09 | J31: =D31/FX_EUR -> 0 | K31: =E31/FX_EUR -> 816966.44 | L31: =F31/FX_EUR -> 4642355.1 | M31: =G31/FX_EUR -> 8895921.1 | N31: =H31/FX_EUR -> 13969774
A32: Revenue per active client a month (ARPA) | B32: FCFA / month | D32: ='Unit economics'!D13 -> 34257.004 | E32: ='Unit economics'!E13 -> 42293.895 | F32: ='Unit economics'!F13 -> 51837.732 | G32: ='Unit economics'!G13 -> 54865.1 | H32: ='Unit economics'!H13 -> 56076.958 | J32: =D32/FX_EUR -> 52.224466 | K32: =E32/FX_EUR -> 64.476627 | L32: =F32/FX_EUR -> 79.026114 | M32: =G32/FX_EUR -> 83.641305 | N32: =H32/FX_EUR -> 85.488772
A33: Blended CAC | B33: FCFA / client | D33: ='Unit economics'!D20 -> 175920.11 | E33: ='Unit economics'!E20 -> 104908.1 | F33: ='Unit economics'!F20 -> 87505.933 | G33: ='Unit economics'!G20 -> 79715.404 | H33: ='Unit economics'!H20 -> 78319.051 | J33: =D33/FX_EUR -> 268.18848 | K33: =E33/FX_EUR -> 159.93137 | L33: =F33/FX_EUR -> 133.40193 | M33: =G33/FX_EUR -> 121.52535 | N33: =H33/FX_EUR -> 119.39662
A34: CAC payback (months) | B34: months | D34: ='Unit economics'!D21 -> 33.969398 | E34: ='Unit economics'!E21 -> 7.6645751 | F34: ='Unit economics'!F21 -> 4.3659435 | G34: ='Unit economics'!G21 -> 3.4923868 | H34: ='Unit economics'!H21 -> 3.2836389
A36: Checks
A37: New-client mix adds up to 100% | B37: =IF(ABS(Mix_Petite+Mix_Moyenne+Mix_Grande-1)<0.0001,"OK","ERROR") -> OK
A38: Cost of revenue in the P&L equals variable costs | B38: =IF(ABS(SUM('P&L monthly'!E24:BL24)-SUM(Costs!E21:BL21))<1,"OK","ERROR") -> OK
A39: Opex in the P&L equals fixed costs | B39: =IF(ABS(SUM('P&L monthly'!E37:BL37)-SUM(Costs!E91:BL91))<1,"OK","ERROR") -> OK
A40: Annual revenue equals monthly revenue | B40: =IF(ABS('P&L annual'!I17-SUM('P&L monthly'!E17:BL17))<1,"OK","ERROR") -> OK
A41: Closing cash never negative | B41: =IF(MIN('Cash flow'!E24:BL24)>=0,"OK","RAISE MORE") -> OK

Sheet Assumptions
A1: Assumptions and hypotheses
A2: Every blue cell on a cream background is an input. Change it and the whole model updates. Amounts in FCFA unless stated. Column D is the value the model uses.
B4: Scenario (1 = Prudent, 2 = Base, 3 = Ambitious) | D4: 2 | E4: =CHOOSE(Scenario,"Prudent","Base","Ambitious") -> Base | I4: Rows with Prudent / Base / Ambitious values switch with this cell.
B7: 1. General | C7: Unit | D7: Value used | E7: Prudent | F7: Base | G7: Ambitious | H7: € / FCFA equivalent | I7: Source / note
B8: Model start (month 1) | C8: date | D8: 46388 | I8: First month of the plan. Company set-up, licence file and product build start here.
B9: FCFA per euro | C9: FCFA | D9: 655.957 | I9: Fixed parity CFA franc / euro (BCEAO).
B10: FCFA per US dollar | C10: FCFA | D10: 580 | I10: Planning rate, used for vendor prices quoted in USD.
B11: Corporate income tax rate | C11: % | D11: 0.3 | I11: Senegal CIT 30%. Simplification: losses carried forward without limit (Senegal allows 3 years). Minimum tax and the 17% TAF on financial services are not modelled.
B12: Annual pay rise (from year 2) | C12: % / year | D12: 0.05 | I12: Applied to every salary each new year.
B13: Contingency on fixed costs | C13: % | D13: 0.05 | I13: Same 5% as the cost breakdown.
B15: 2. Timing (month numbers, 1 = first month of the model) | C15: Unit | D15: Value used | E15: Prudent | F15: Base | G15: Ambitious | H15: € / FCFA equivalent | I15: Source / note
B16: Commercial launch, Senegal | C16: month # | D16: 5 | I16: After partner bank integration and card programme set-up (business account with IBAN via the partner bank).
B17: Commercial launch, Côte d'Ivoire | C17: month # | D17: 19 | I17: One month after the Abidjan office opens. Partners hold the licences in Côte d'Ivoire too.
B18: Dakar office (Regus) from | C18: month # | D18: 1 | I18: Regus from day one: no lease, deposit or fit-out (decision).
B19: Abidjan office (Regus) and first Côte d'Ivoire hires | C19: month # | D19: 18 | I19: Not before month 18 (decision).
B20: Payment links go live | C20: month # | D20: 18 | I20: 'Bientôt' feature in the app.
B21: B2C launch: employee salary accounts and personal accounts | C21: month # | D21: 29 | I21: Not before 2 years of commercial activity: Senegal launch + 24 months (decision).
B22: Acquisition of a microfinance company (SFD) closes | C22: month # | D22: 24 | I22: Around year 2 (decision). Due diligence and the change-of-control approval run during year 2.
B23: Own SFD lends from | C23: month # | D23: 25 | I23: Before this month the partner SFD lends and Tabax keeps a share of the margin. Côte d'Ivoire loans stay with a partner: SFD licences are national.
B24: Card programme collateral at partner bank | C24: month # | D24: 4
B25: Partner bank set-up fee paid, Senegal | C25: month # | D25: 2
B26: Partner bank set-up fee paid, Côte d'Ivoire | C26: month # | D26: 16
B27: Card processor set-up fee paid | C27: month # | D27: 3
B28: Card processor monthly minimum starts | C28: month # | D28: 5
B29: Cloud hosting starts | C29: month # | D29: 2
B30: Partner SFD integration fee paid | C30: month # | D30: 15 | I30: Partner SFD signed early; integration paid before the first loans.
B31: Côte d'Ivoire subsidiary created | C31: month # | D31: 16 | I31: Before the first Abidjan hires.
B32: First tech audit (then every 12 months) | C32: month # | D32: 4 | I32: Before launch, for the partner bank; repeated yearly.
B34: 3. Client acquisition (sales and marketing) | C34: Unit | D34: Value used | E34: Prudent | F34: Base | G34: Ambitious | H34: € / FCFA equivalent | I34: Source / note
B35: New clients signed per field sales rep per month | C35: clients | D35: =CHOOSE(Scenario,E35,F35,G35) -> 10 | E35: 7 | F35: 10 | G35: 13 | I35: Rep counts come from the hiring plan. A rep sells from the month after joining. Senegal B2B field sales benchmark to validate in the pilot.
B36: Côte d'Ivoire rep productivity vs Senegal | C36: x | D36: 0.9 | I36: Slightly lower at first: new market, brand unknown.
B37: Partner channel, Senegal: clients a month at launch | C37: clients | D37: =CHOOSE(Scenario,E37,F37,G37) -> 10 | E37: 6 | F37: 10 | G37: 14 | I37: Accountants, payroll software, chambers of commerce.
B38: Partner channel, Côte d'Ivoire: clients a month at launch | C38: clients | D38: =CHOOSE(Scenario,E38,F38,G38) -> 6 | E38: 4 | F38: 6 | G38: 9
B39: Partner channel monthly growth | C39: % / month | D39: 0.06
B40: Partner channel cap, Senegal | C40: clients / month | D40: 80
B41: Partner channel cap, Côte d'Ivoire | C41: clients / month | D41: 60
B42: Digital ads cost per signed client | C42: FCFA | D42: =CHOOSE(Scenario,E42,F42,G42) -> 75000 | E42: 100000 | F42: 75000 | G42: 55000 | H42: =D42/FX_EUR -> 114.33676 | I42: Media spend only. Meta leads 600–2,800 FCFA; lead-to-client conversion assumed 2–4%.
B43: Share of new clients on Petite (1–10 staff) | C43: % | D43: 0.6 | I43: From Business model v2. The three shares must add up to 100% (see check on the Dashboard).
B44: Share of new clients on Moyenne (11–50 staff) | C44: % | D44: 0.3
B45: Share of new clients on Grande (51+ staff) | C45: % | D45: 0.1
...

Sheet Unit costs
A1: Unit costs and prices
A2: What one of each thing costs or earns, in FCFA and euros. Every cell links to the inputs on Assumptions and Hiring plan: change them there.
A5: One employee, per month
A6: Employer cost plus what each person adds: Regus desk, phone, Gmail and ClickUp, a Claude seat for the CTO and developers. One-off at hiring: a laptop (a MacBook for the CTO and developers), plus the agency fee for senior roles.
A7: Role | B7: Country | C7: Agency hire | D7: Gross salary | E7: Employer charges | F7: Employer cost | G7: Office (Regus) | H7: Phone and data | I7: Gmail and ClickUp | J7: Claude seat | K7: All-in per month (FCFA) | L7: All-in per month (€) | M7: One-off at hiring (FCFA) | N7: One-off at hiring (€)
A8: ='Hiring plan'!C5 -> CEO (full salary from year 2) | B8: ='Hiring plan'!D5 -> SN | C8: ='Hiring plan'!J5 -> Y | D8: ='Hiring plan'!I5 -> 2500000 | E8: =D8*Employer_Charges -> 750000 | F8: =D8+E8 -> 3250000 | G8: =Regus_EUR*FX_EUR -> 196787.1 | H8: =Phone_Cost -> 5000 | I8: =(Gmail_USD+ClickUp_USD)*FX_USD -> 10440 | J8: =IF('Hiring plan'!B5="Engineering & product",Claude_USD*FX_USD,0) -> 0 | K8: =SUM(F8:J8) -> 3462227.1 | L8: =K8/FX_EUR -> 5278.1312 | M8: =IF('Hiring plan'!B5="Engineering & product",Laptop_Dev_USD*FX_USD,Laptop_EUR*FX_EUR)+IF(C8="Y",Agency_Fee_EUR*FX_EUR,0) -> 852744.1 | N8: =M8/FX_EUR -> 1300
A9: ='Hiring plan'!C6 -> CTO (also codes) | B9: ='Hiring plan'!D6 -> SN | C9: ='Hiring plan'!J6 -> Y | D9: ='Hiring plan'!I6 -> 2500000 | E9: =D9*Employer_Charges -> 750000 | F9: =D9+E9 -> 3250000 | G9: =Regus_EUR*FX_EUR -> 196787.1 | H9: =Phone_Cost -> 5000 | I9: =(Gmail_USD+ClickUp_USD)*FX_USD -> 10440 | J9: =IF('Hiring plan'!B6="Engineering & product",Claude_USD*FX_USD,0) -> 14500 | K9: =SUM(F9:J9) -> 3476727.1 | L9: =K9/FX_EUR -> 5300.2363 | M9: =IF('Hiring plan'!B6="Engineering & product",Laptop_Dev_USD*FX_USD,Laptop_EUR*FX_EUR)+IF(C9="Y",Agency_Fee_EUR*FX_EUR,0) -> 1684765.6 | N9: =M9/FX_EUR -> 2568.4086
A10: ='Hiring plan'!C7 -> Financial expert (finance, partners, credit lead) | B10: ='Hiring plan'!D7 -> SN | C10: ='Hiring plan'!J7 -> Y | D10: ='Hiring plan'!I7 -> 1500000 | E10: =D10*Employer_Charges -> 450000 | F10: =D10+E10 -> 1950000 | G10: =Regus_EUR*FX_EUR -> 196787.1 | H10: =Phone_Cost -> 5000 | I10: =(Gmail_USD+ClickUp_USD)*FX_USD -> 10440 | J10: =IF('Hiring plan'!B7="Engineering & product",Claude_USD*FX_USD,0) -> 0 | K10: =SUM(F10:J10) -> 2162227.1 | L10: =K10/FX_EUR -> 3296.294 | M10: =IF('Hiring plan'!B7="Engineering & product",Laptop_Dev_USD*FX_USD,Laptop_EUR*FX_EUR)+IF(C10="Y",Agency_Fee_EUR*FX_EUR,0) -> 852744.1 | N10: =M10/FX_EUR -> 1300
A11: ='Hiring plan'!C8 -> Sales lead (also sells; incl. bonus) | B11: ='Hiring plan'!D8 -> SN | C11: ='Hiring plan'!J8 -> N | D11: ='Hiring plan'!I8 -> 1200000 | E11: =D11*Employer_Charges -> 360000 | F11: =D11+E11 -> 1560000 | G11: =Regus_EUR*FX_EUR -> 196787.1 | H11: =Phone_Cost -> 5000 | I11: =(Gmail_USD+ClickUp_USD)*FX_USD -> 10440 | J11: =IF('Hiring plan'!B8="Engineering & product",Claude_USD*FX_USD,0) -> 0 | K11: =SUM(F11:J11) -> 1772227.1 | L11: =K11/FX_EUR -> 2701.7428 | M11: =IF('Hiring plan'!B8="Engineering & product",Laptop_Dev_USD*FX_USD,Laptop_EUR*FX_EUR)+IF(C11="Y",Agency_Fee_EUR*FX_EUR,0) -> 327978.5 | N11: =M11/FX_EUR -> 500
A12: ='Hiring plan'!C9 -> Marketing manager (senior) | B12: ='Hiring plan'!D9 -> SN | C12: ='Hiring plan'!J9 -> N | D12: ='Hiring plan'!I9 -> 900000 | E12: =D12*Employer_Charges -> 270000 | F12: =D12+E12 -> 1170000 | G12: =Regus_EUR*FX_EUR -> 196787.1 | H12: =Phone_Cost -> 5000 | I12: =(Gmail_USD+ClickUp_USD)*FX_USD -> 10440 | J12: =IF('Hiring plan'!B9="Engineering & product",Claude_USD*FX_USD,0) -> 0 | K12: =SUM(F12:J12) -> 1382227.1 | L12: =K12/FX_EUR -> 2107.1916 | M12: =IF('Hiring plan'!B9="Engineering & product",Laptop_Dev_USD*FX_USD,Laptop_EUR*FX_EUR)+IF(C12="Y",Agency_Fee_EUR*FX_EUR,0) -> 327978.5 | N12: =M12/FX_EUR -> 500
A13: ='Hiring plan'!C10 -> Marketing officer (junior) | B13: ='Hiring plan'!D10 -> SN | C13: ='Hiring plan'!J10 -> N | D13: ='Hiring plan'!I10 -> 400000 | E13: =D13*Employer_Charges -> 120000 | F13: =D13+E13 -> 520000 | G13: =Regus_EUR*FX_EUR -> 196787.1 | H13: =Phone_Cost -> 5000 | I13: =(Gmail_USD+ClickUp_USD)*FX_USD -> 10440 | J13: =IF('Hiring plan'!B10="Engineering & product",Claude_USD*FX_USD,0) -> 0 | K13: =SUM(F13:J13) -> 732227.1 | L13: =K13/FX_EUR -> 1116.273 | M13: =IF('Hiring plan'!B10="Engineering & product",Laptop_Dev_USD*FX_USD,Laptop_EUR*FX_EUR)+IF(C13="Y",Agency_Fee_EUR*FX_EUR,0) -> 327978.5 | N13: =M13/FX_EUR -> 500
A14: ='Hiring plan'!C11 -> Country manager, Abidjan | B14: ='Hiring plan'!D11 -> CI | C14: ='Hiring plan'!J11 -> Y | D14: ='Hiring plan'!I11 -> 2800000 | E14: =D14*Employer_Charges -> 840000 | F14: =D14+E14 -> 3640000 | G14: =Regus_EUR*FX_EUR -> 196787.1 | H14: =Phone_Cost -> 5000 | I14: =(Gmail_USD+ClickUp_USD)*FX_USD -> 10440 | J14: =IF('Hiring plan'!B11="Engineering & product",Claude_USD*FX_USD,0) -> 0 | K14: =SUM(F14:J14) -> 3852227.1 | L14: =K14/FX_EUR -> 5872.6824 | M14: =IF('Hiring plan'!B11="Engineering & product",Laptop_Dev_USD*FX_USD,Laptop_EUR*FX_EUR)+IF(C14="Y",Agency_Fee_EUR*FX_EUR,0) -> 852744.1 | N14: =M14/FX_EUR -> 1300
A15: ='Hiring plan'!C12 -> Compliance officer (AML/CFT) | B15: ='Hiring plan'!D12 -> SN | C15: ='Hiring plan'!J12 -> Y | D15: ='Hiring plan'!I12 -> 1500000 | E15: =D15*Employer_Charges -> 450000 | F15: =D15+E15 -> 1950000 | G15: =Regus_EUR*FX_EUR -> 196787.1 | H15: =Phone_Cost -> 5000 | I15: =(Gmail_USD+ClickUp_USD)*FX_USD -> 10440 | J15: =IF('Hiring plan'!B12="Engineering & product",Claude_USD*FX_USD,0) -> 0 | K15: =SUM(F15:J15) -> 2162227.1 | L15: =K15/FX_EUR -> 3296.294 | M15: =IF('Hiring plan'!B12="Engineering & product",Laptop_Dev_USD*FX_USD,Laptop_EUR*FX_EUR)+IF(C15="Y",Agency_Fee_EUR*FX_EUR,0) -> 852744.1 | N15: =M15/FX_EUR -> 1300
A16: Customer support agent (grows with volume) | B16: SN | C16: =IF(Agency_Support=1,"Y","N") -> N | D16: =Salary_Support -> 250000 | E16: =D16*Employer_Charges -> 75000 | F16: =D16+E16 -> 325000 | G16: =Regus_EUR*FX_EUR -> 196787.1 | H16: =Phone_Cost -> 5000 | I16: =(Gmail_USD+ClickUp_USD)*FX_USD -> 10440 | J16: =0 -> 0 | K16: =SUM(F16:J16) -> 537227.1 | L16: =K16/FX_EUR -> 818.99743 | M16: =IF(FALSE(),Laptop_Dev_USD*FX_USD,Laptop_EUR*FX_EUR)+IF(C16="Y",Agency_Fee_EUR*FX_EUR,0) -> 327978.5 | N16: =M16/FX_EUR -> 500
A17: Developer (grows with volume) | B17: SN | C17: =IF(Agency_Dev=1,"Y","N") -> Y | D17: =Salary_Dev -> 1200000 | E17: =D17*Employer_Charges -> 360000 | F17: =D17+E17 -> 1560000 | G17: =Regus_EUR*FX_EUR -> 196787.1 | H17: =Phone_Cost -> 5000 | I17: =(Gmail_USD+ClickUp_USD)*FX_USD -> 10440 | J17: =Claude_USD*FX_USD -> 14500 | K17: =SUM(F17:J17) -> 1786727.1 | L17: =K17/FX_EUR -> 2723.8479 | M17: =IF(TRUE(),Laptop_Dev_USD*FX_USD,Laptop_EUR*FX_EUR)+IF(C17="Y",Agency_Fee_EUR*FX_EUR,0) -> 1684765.6 | N17: =M17/FX_EUR -> 2568.4086
A18: Field sales rep, Senegal (grows with volume) | B18: SN | C18: =IF(Agency_Rep=1,"Y","N") -> N | D18: =Salary_Rep_SN -> 400000 | E18: =D18*Employer_Charges -> 120000 | F18: =D18+E18 -> 520000 | G18: =Regus_EUR*FX_EUR -> 196787.1 | H18: =Phone_Cost -> 5000 | I18: =(Gmail_USD+ClickUp_USD)*FX_USD -> 10440 | J18: =0 -> 0 | K18: =SUM(F18:J18) -> 732227.1 | L18: =K18/FX_EUR -> 1116.273 | M18: =IF(FALSE(),Laptop_Dev_USD*FX_USD,Laptop_EUR*FX_EUR)+IF(C18="Y",Agency_Fee_EUR*FX_EUR,0) -> 327978.5 | N18: =M18/FX_EUR -> 500
A19: Field sales rep, Côte d'Ivoire (grows with volume) | B19: CI | C19: =IF(Agency_Rep=1,"Y","N") -> N | D19: =Salary_Rep_CI -> 450000 | E19: =D19*Employer_Charges -> 135000 | F19: =D19+E19 -> 585000 | G19: =Regus_EUR*FX_EUR -> 196787.1 | H19: =Phone_Cost -> 5000 | I19: =(Gmail_USD+ClickUp_USD)*FX_USD -> 10440 | J19: =0 -> 0 | K19: =SUM(F19:J19) -> 797227.1 | L19: =K19/FX_EUR -> 1215.3649 | M19: =IF(FALSE(),Laptop_Dev_USD*FX_USD,Laptop_EUR*FX_EUR)+IF(C19="Y",Agency_Fee_EUR*FX_EUR,0) -> 327978.5 | N19: =M19/FX_EUR -> 500
A20: Credit analyst (grows with volume) | B20: SN | C20: =IF(Agency_Credit=1,"Y","N") -> Y | D20: =Salary_Credit -> 600000 | E20: =D20*Employer_Charges -> 180000 | F20: =D20+E20 -> 780000 | G20: =Regus_EUR*FX_EUR -> 196787.1 | H20: =Phone_Cost -> 5000 | I20: =(Gmail_USD+ClickUp_USD)*FX_USD -> 10440 | J20: =0 -> 0 | K20: =SUM(F20:J20) -> 992227.1 | L20: =K20/FX_EUR -> 1512.6405 | M20: =IF(FALSE(),Laptop_Dev_USD*FX_USD,Laptop_EUR*FX_EUR)+IF(C20="Y",Agency_Fee_EUR*FX_EUR,0) -> 852744.1 | N20: =M20/FX_EUR -> 1300
A21: Company-wide, not per person: 2 shared Claude seats, the website and domain. Field reps also get the transport allowance (Sales & marketing). Pay rises 5% a year from year 2.
A23: One business client, per month, by plan
A24: Steady state: after the free months, payment links at full adoption, no credit. Scenario inputs at their current value.
A25: Line | B25: How it is calculated | D25: Petite | E25: Moyenne | F25: Grande | G25: Petite (€) | H25: Moyenne (€) | I25: Grande (€)
A26: Revenue
A27: Subscription (after the yearly-billing discount) | B27: Plan price × (1 − share paying yearly × free months on yearly billing ÷ 12) | D27: =Price_Petite*(1-Annual_Share*Annual_Free/12) -> 9405 | E27: =Price_Moyenne*(1-Annual_Share*Annual_Free/12) -> 28405 | F27: =Price_Grande*(1-Annual_Share*Annual_Free/12) -> 75905 | G27: =D27/FX_EUR -> 14.33783 | H27: =E27/FX_EUR -> 43.303143 | I27: =F27/FX_EUR -> 115.71643
A28: Fees on foreign-currency card spending | B28: Foreign-currency card spending × FX fee | D28: =Spend_For_Petite*FX_Fee -> 3000 | E28: =Spend_For_Moyenne*FX_Fee -> 12000 | F28: =Spend_For_Grande*FX_Fee -> 35000 | G28: =D28/FX_EUR -> 4.5734705 | H28: =E28/FX_EUR -> 18.293882 | I28: =F28/FX_EUR -> 53.357156
A29: Interchange share | B29: FCFA card spending × interchange share | D29: =Spend_Dom_Petite*Interchange_Share -> 1500 | E29: =Spend_Dom_Moyenne*Interchange_Share -> 4000 | F29: =Spend_Dom_Grande*Interchange_Share -> 12500 | G29: =D29/FX_EUR -> 2.2867353 | H29: =E29/FX_EUR -> 6.0979607 | I29: =F29/FX_EUR -> 19.056127
A30: Share of bank income on balances | B30: Average balance × yearly share ÷ 12 | D30: =Balance_Petite*Deposit_Share/12 -> 3750 | E30: =Balance_Moyenne*Deposit_Share/12 -> 12500 | F30: =Balance_Grande*Deposit_Share/12 -> 50000 | G30: =D30/FX_EUR -> 5.7168381 | H30: =E30/FX_EUR -> 19.056127 | I30: =F30/FX_EUR -> 76.224509
A31: Fees on supplier payouts above the allowance | B31: Payouts above the allowance × fee per payout | D31: =Overage_Petite*Overage_Fee -> 0 | E31: =Overage_Moyenne*Overage_Fee -> 500 | F31: =Overage_Grande*Overage_Fee -> 4000 | G31: =D31/FX_EUR -> 0 | H31: =E31/FX_EUR -> 0.76224509 | I31: =F31/FX_EUR -> 6.0979607
A32: Payment link fees (average client) | B32: Collections × adoption × share by mobile money × fee | D32: =PL_Coll_Petite*PL_Adoption*PL_Momo_Share*PL_Fee -> 1400 | E32: =PL_Coll_Moyenne*PL_Adoption*PL_Momo_Share*PL_Fee -> 5250 | F32: =PL_Coll_Grande*PL_Adoption*PL_Momo_Share*PL_Fee -> 17500 | G32: =D32/FX_EUR -> 2.1342862 | H32: =E32/FX_EUR -> 8.0035734 | I32: =F32/FX_EUR -> 26.678578
A33: Revenue per client | D33: =SUM(D27:D32) -> 19055 | E33: =SUM(E27:E32) -> 62655 | F33: =SUM(F27:F32) -> 194905 | G33: =D33/FX_EUR -> 29.04916 | H33: =E33/FX_EUR -> 95.516932 | I33: =F33/FX_EUR -> 297.13076
A34: Cost to serve
A35: Partner bank fee per business account | B35: Flat fee per account | D35: =Bank_Fee -> 3000 | E35: =Bank_Fee -> 3000 | F35: =Bank_Fee -> 3000 | G35: =D35/FX_EUR -> 4.5734705 | H35: =E35/FX_EUR -> 4.5734705 | I35: =F35/FX_EUR -> 4.5734705
A36: Card processing | B36: Active cards × processing fee per card | D36: =Cards_Act_Petite*Card_Proc_Fee -> 2000 | E36: =Cards_Act_Moyenne*Card_Proc_Fee -> 6000 | F36: =Cards_Act_Grande*Card_Proc_Fee -> 15000 | G36: =D36/FX_EUR -> 3.0489803 | H36: =E36/FX_EUR -> 9.146941 | I36: =F36/FX_EUR -> 22.867353
A37: Visa / Mastercard cross-border fees | B37: Foreign-currency card spending × scheme rate | D37: =Spend_For_Petite*Scheme_Rate -> 1500 | E37: =Spend_For_Moyenne*Scheme_Rate -> 6000 | F37: =Spend_For_Grande*Scheme_Rate -> 17500 | G37: =D37/FX_EUR -> 2.2867353 | H37: =E37/FX_EUR -> 9.146941 | I37: =F37/FX_EUR -> 26.678578
A38: Fraud and chargebacks | B38: All card spending × fraud rate | D38: =(Spend_Dom_Petite+Spend_For_Petite)*Fraud_Rate -> 900 | E38: =(Spend_Dom_Moyenne+Spend_For_Moyenne)*Fraud_Rate -> 3000 | F38: =(Spend_Dom_Grande+Spend_For_Grande)*Fraud_Rate -> 9000 | G38: =D38/FX_EUR -> 1.3720412 | H38: =E38/FX_EUR -> 4.5734705 | I38: =F38/FX_EUR -> 13.720412
A39: Salaries paid to mobile wallets | B39: Employees × average salary × share to wallets × cost rate | D39: =Emp_Petite*Avg_Salary*Wallet_Share*Wallet_Payout_Cost -> 1500 | E39: =Emp_Moyenne*Avg_Salary*Wallet_Share*Wallet_Payout_Cost -> 7500 | F39: =Emp_Grande*Avg_Salary*Wallet_Share*Wallet_Payout_Cost -> 36000 | G39: =D39/FX_EUR -> 2.2867353 | H39: =E39/FX_EUR -> 11.433676 | I39: =F39/FX_EUR -> 54.881646
A40: Salaries paid to bank accounts | B40: Employees × share to banks × cost per transfer | D40: =Emp_Petite*(1-Wallet_Share)*Bank_Payout_Cost -> 200 | E40: =Emp_Moyenne*(1-Wallet_Share)*Bank_Payout_Cost -> 1000 | F40: =Emp_Grande*(1-Wallet_Share)*Bank_Payout_Cost -> 4800 | G40: =D40/FX_EUR -> 0.30489803 | H40: =E40/FX_EUR -> 1.5244902 | I40: =F40/FX_EUR -> 7.3175528
A41: Supplier payouts | B41: Payouts × cost per payout | D41: =Supplier_Petite*Supplier_Payout_Cost -> 1000 | E41: =Supplier_Moyenne*Supplier_Payout_Cost -> 4000 | F41: =Supplier_Grande*Supplier_Payout_Cost -> 15000 | G41: =D41/FX_EUR -> 1.5244902 | H41: =E41/FX_EUR -> 6.0979607 | I41: =F41/FX_EUR -> 22.867353
A42: Payment link collection costs | B42: Collections × adoption × share by mobile money × operator cost | D42: =PL_Coll_Petite*PL_Adoption*PL_Momo_Share*PL_Cost -> 980 | E42: =PL_Coll_Moyenne*PL_Adoption*PL_Momo_Share*PL_Cost -> 3675 | F42: =PL_Coll_Grande*PL_Adoption*PL_Momo_Share*PL_Cost -> 12250 | G42: =D42/FX_EUR -> 1.4940004 | H42: =E42/FX_EUR -> 5.6025014 | I42: =F42/FX_EUR -> 18.675005
A43: SMS, WhatsApp and support tools | B43: Flat per client | D43: =Notif_Cost -> 400 | E43: =Notif_Cost -> 400 | F43: =Notif_Cost -> 400 | G43: =D43/FX_EUR -> 0.60979607 | H43: =E43/FX_EUR -> 0.60979607 | I43: =F43/FX_EUR -> 0.60979607
...

Sheet Hiring plan
A1: Hiring plan
A2: One line per hire or group of identical hires. Edit headcount, start month, end month (leave blank if they stay) and gross salary. Spare lines at the bottom for new roles.
A4: # | B4: Department | C4: Role | D4: Country | E4: Category | F4: Headcount | G4: Start month | H4: End month | I4: Gross salary (FCFA / month) | J4: Agency hire (Y/N) | K4: Employer cost per person (FCFA / month) | L4: Note | M4: Gross salary (€ / month) | N4: Employer cost per person (€ / month)
A5: 1 | B5: Leadership | C5: CEO (full salary from year 2) | D5: SN | F5: 1 | G5: 13 | I5: 2500000 | J5: Y | K5: =IF(I5="",0,I5*(1+Employer_Charges)) -> 3250000 | L5: Founders and shareholders run the company unpaid in year 1 (decision). | M5: =IF(N(I5)=0,0,I5/FX_EUR) -> 3811.2254 | N5: =IF(N(K5)=0,0,K5/FX_EUR) -> 4954.5931
A6: 2 | B6: Engineering & product | C6: CTO (also codes) | D6: SN | F6: 1 | G6: 1 | I6: 2500000 | J6: Y | K6: =IF(I6="",0,I6*(1+Employer_Charges)) -> 3250000 | L6: Developers are added with volume on the Staff sheet (2 at the start). | M6: =IF(N(I6)=0,0,I6/FX_EUR) -> 3811.2254 | N6: =IF(N(K6)=0,0,K6/FX_EUR) -> 4954.5931
A7: 3 | B7: Finance & admin | C7: Financial expert (finance, partners, credit lead) | D7: SN | F7: 1 | G7: 1 | I7: 1500000 | J7: Y | K7: =IF(I7="",0,I7*(1+Employer_Charges)) -> 1950000 | L7: Starting team. Credit analysts are added with the loan book. | M7: =IF(N(I7)=0,0,I7/FX_EUR) -> 2286.7353 | N7: =IF(N(K7)=0,0,K7/FX_EUR) -> 2972.7558
A8: 4 | B8: Sales & partnerships | C8: Sales lead (also sells; incl. bonus) | D8: SN | E8: Sales rep | F8: 1 | G8: 1 | I8: 1200000 | J8: N | K8: =IF(I8="",0,I8*(1+Employer_Charges)) -> 1560000 | L8: Plus 2 field reps from month 4, then reps grow with clients (Staff sheet). | M8: =IF(N(I8)=0,0,I8/FX_EUR) -> 1829.3882 | N8: =IF(N(K8)=0,0,K8/FX_EUR) -> 2378.2047
A9: 5 | B9: Marketing | C9: Marketing manager (senior) | D9: SN | F9: 1 | G9: 4 | I9: 900000 | J9: N | K9: =IF(I9="",0,I9*(1+Employer_Charges)) -> 1170000 | L9: Prepares the launch; runs digital ads and partnerships. | M9: =IF(N(I9)=0,0,I9/FX_EUR) -> 1372.0412 | N9: =IF(N(K9)=0,0,K9/FX_EUR) -> 1783.6535
A10: 6 | B10: Marketing | C10: Marketing officer (junior) | D10: SN | F10: 1 | G10: 5 | I10: 400000 | J10: N | K10: =IF(I10="",0,I10*(1+Employer_Charges)) -> 520000 | L10: Content, social media, events. | M10: =IF(N(I10)=0,0,I10/FX_EUR) -> 609.79607 | N10: =IF(N(K10)=0,0,K10/FX_EUR) -> 792.73489
A11: 7 | B11: Leadership | C11: Country manager, Abidjan | D11: CI | F11: 1 | G11: =CI_Office_Start -> 18 | I11: 2800000 | J11: Y | K11: =IF(I11="",0,I11*(1+Employer_Charges)) -> 3640000 | L11: Joins when the Abidjan office opens. | M11: =IF(N(I11)=0,0,I11/FX_EUR) -> 4268.5725 | N11: =IF(N(K11)=0,0,K11/FX_EUR) -> 5549.1442
A12: 8 | B12: Compliance & risk | C12: Compliance officer (AML/CFT) | D12: SN | F12: 1 | G12: =SFD_Acq_Month -> 24 | I12: 1500000 | J12: Y | K12: =IF(I12="",0,I12*(1+Employer_Charges)) -> 1950000 | L12: Required once Tabax holds its own licence (SFD). | M12: =IF(N(I12)=0,0,I12/FX_EUR) -> 2286.7353 | N12: =IF(N(K12)=0,0,K12/FX_EUR) -> 2972.7558
A13: 9 | K13: =IF(I13="",0,I13*(1+Employer_Charges)) -> 0 | M13: =IF(N(I13)=0,0,I13/FX_EUR) -> 0 | N13: =IF(N(K13)=0,0,K13/FX_EUR) -> 0
A14: 10 | K14: =IF(I14="",0,I14*(1+Employer_Charges)) -> 0 | M14: =IF(N(I14)=0,0,I14/FX_EUR) -> 0 | N14: =IF(N(K14)=0,0,K14/FX_EUR) -> 0
A15: 11 | K15: =IF(I15="",0,I15*(1+Employer_Charges)) -> 0 | M15: =IF(N(I15)=0,0,I15/FX_EUR) -> 0 | N15: =IF(N(K15)=0,0,K15/FX_EUR) -> 0
A16: 12 | K16: =IF(I16="",0,I16*(1+Employer_Charges)) -> 0 | M16: =IF(N(I16)=0,0,I16/FX_EUR) -> 0 | N16: =IF(N(K16)=0,0,K16/FX_EUR) -> 0
A17: 13 | K17: =IF(I17="",0,I17*(1+Employer_Charges)) -> 0 | M17: =IF(N(I17)=0,0,I17/FX_EUR) -> 0 | N17: =IF(N(K17)=0,0,K17/FX_EUR) -> 0
A18: 14 | K18: =IF(I18="",0,I18*(1+Employer_Charges)) -> 0 | M18: =IF(N(I18)=0,0,I18/FX_EUR) -> 0 | N18: =IF(N(K18)=0,0,K18/FX_EUR) -> 0
A19: 15 | K19: =IF(I19="",0,I19*(1+Employer_Charges)) -> 0 | M19: =IF(N(I19)=0,0,I19/FX_EUR) -> 0 | N19: =IF(N(K19)=0,0,K19/FX_EUR) -> 0
A20: 16 | K20: =IF(I20="",0,I20*(1+Employer_Charges)) -> 0 | M20: =IF(N(I20)=0,0,I20/FX_EUR) -> 0 | N20: =IF(N(K20)=0,0,K20/FX_EUR) -> 0
A21: 17 | K21: =IF(I21="",0,I21*(1+Employer_Charges)) -> 0 | M21: =IF(N(I21)=0,0,I21/FX_EUR) -> 0 | N21: =IF(N(K21)=0,0,K21/FX_EUR) -> 0
A22: 18 | K22: =IF(I22="",0,I22*(1+Employer_Charges)) -> 0 | M22: =IF(N(I22)=0,0,I22/FX_EUR) -> 0 | N22: =IF(N(K22)=0,0,K22/FX_EUR) -> 0
A23: 19 | K23: =IF(I23="",0,I23*(1+Employer_Charges)) -> 0 | M23: =IF(N(I23)=0,0,I23/FX_EUR) -> 0 | N23: =IF(N(K23)=0,0,K23/FX_EUR) -> 0
A24: 20 | K24: =IF(I24="",0,I24*(1+Employer_Charges)) -> 0 | M24: =IF(N(I24)=0,0,I24/FX_EUR) -> 0 | N24: =IF(N(K24)=0,0,K24/FX_EUR) -> 0
... A32: 28 | K32: =IF(I32="",0,I32*(1+Employer_Charges)) -> 0 | M32: =IF(N(I32)=0,0,I32/FX_EUR) -> 0 | N32: =IF(N(K32)=0,0,K32/FX_EUR) -> 0
B34: Employer cost = gross salary × (1 + employer charges), 30% on Assumptions section 8. Customer support, developers, field sales reps and credit analysts grow with volume: see the Staff sheet and the ratios on Assumptions section 8.

Sheet Staff
A1: Staff
A2: Headcount and employer cost by month, from the hiring plan. Pay rises each year by the rate on Assumptions.
A3: Month # | D3: Total / end | E3: 1 | F3: =E3+1 -> 2 | G3: =F3+1 -> 3 | H3: =G3+1 -> 4 | I3: =H3+1 -> 5 | J3: =I3+1 -> 6 | K3: =J3+1 -> 7 | L3: =K3+1 -> 8 | M3: =L3+1 -> 9 | ... BL3: =BK3+1 -> 60
A4: Month | E4: =DATE(YEAR(Start_Date),MONTH(Start_Date)+E3-1,1) -> 46388 | F4: =DATE(YEAR(Start_Date),MONTH(Start_Date)+F3-1,1) -> 46419 | G4: =DATE(YEAR(Start_Date),MONTH(Start_Date)+G3-1,1) -> 46447 | H4: =DATE(YEAR(Start_Date),MONTH(Start_Date)+H3-1,1) -> 46478 | I4: =DATE(YEAR(Start_Date),MONTH(Start_Date)+I3-1,1) -> 46508 | J4: =DATE(YEAR(Start_Date),MONTH(Start_Date)+J3-1,1) -> 46539 | K4: =DATE(YEAR(Start_Date),MONTH(Start_Date)+K3-1,1) -> 46569 | L4: =DATE(YEAR(Start_Date),MONTH(Start_Date)+L3-1,1) -> 46600 | ... BL4: =DATE(YEAR(Start_Date),MONTH(Start_Date)+BL3-1,1) -> 48183
A5: Year | E5: =INT((E3-1)/12)+1 -> 1 | F5: =INT((F3-1)/12)+1 -> 1 | G5: =INT((G3-1)/12)+1 -> 1 | H5: =INT((H3-1)/12)+1 -> 1 | I5: =INT((I3-1)/12)+1 -> 1 | J5: =INT((J3-1)/12)+1 -> 1 | K5: =INT((K3-1)/12)+1 -> 1 | L5: =INT((L3-1)/12)+1 -> 1 | ... BL5: =INT((BL3-1)/12)+1 -> 5
A8: Headcount by hire line
A9: =IF('Hiring plan'!$C$5="","(spare line 1)",'Hiring plan'!$C$5&" · "&'Hiring plan'!$D$5) -> CEO (full salary from year 2) · SN | B9: people | D9: =MAX(E9:BL9) -> 1 | E9: =IF(AND(N('Hiring plan'!$F$5)>0,E$3>='Hiring plan'!$G$5,E$3<=IF('Hiring plan'!$H$5="",999,'Hiring plan'!$H$5)),'Hiring plan'!$F$5,0) -> 0 | F9: =IF(AND(N('Hiring plan'!$F$5)>0,F$3>='Hiring plan'!$G$5,F$3<=IF('Hiring plan'!$H$5="",999,'Hiring plan'!$H$5)),'Hiring plan'!$F$5,0) -> 0 | G9: =IF(AND(N('Hiring plan'!$F$5)>0,G$3>='Hiring plan'!$G$5,G$3<=IF('Hiring plan'!$H$5="",999,'Hiring plan'!$H$5)),'Hiring plan'!$F$5,0) -> 0 | H9: =IF(AND(N('Hiring plan'!$F$5)>0,H$3>='Hiring plan'!$G$5,H$3<=IF('Hiring plan'!$H$5="",999,'Hiring plan'!$H$5)),'Hiring plan'!$F$5,0) -> 0 | I9: =IF(AND(N('Hiring plan'!$F$5)>0,I$3>='Hiring plan'!$G$5,I$3<=IF('Hiring plan'!$H$5="",999,'Hiring plan'!$H$5)),'Hiring plan'!$F$5,0) -> 0 | J9: =IF(AND(N('Hiring plan'!$F$5)>0,J$3>='Hiring plan'!$G$5,J$3<=IF('Hiring plan'!$H$5="",999,'Hiring plan'!$H$5)),'Hiring plan'!$F$5,0) -> 0 | K9: =IF(AND(N('Hiring plan'!$F$5)>0,K$3>='Hiring plan'!$G$5,K$3<=IF('Hiring plan'!$H$5="",999,'Hiring plan'!$H$5)),'Hiring plan'!$F$5,0) -> 0 | L9: =IF(AND(N('Hiring plan'!$F$5)>0,L$3>='Hiring plan'!$G$5,L$3<=IF('Hiring plan'!$H$5="",999,'Hiring plan'!$H$5)),'Hiring plan'!$F$5,0) -> 0 | ... BL9: =IF(AND(N('Hiring plan'!$F$5)>0,BL$3>='Hiring plan'!$G$5,BL$3<=IF('Hiring plan'!$H$5="",999,'Hiring plan'!$H$5)),'Hiring plan'!$F$5,0) -> 1
A10: =IF('Hiring plan'!$C$6="","(spare line 2)",'Hiring plan'!$C$6&" · "&'Hiring plan'!$D$6) -> CTO (also codes) · SN | B10: people | D10: =MAX(E10:BL10) -> 1 | E10: =IF(AND(N('Hiring plan'!$F$6)>0,E$3>='Hiring plan'!$G$6,E$3<=IF('Hiring plan'!$H$6="",999,'Hiring plan'!$H$6)),'Hiring plan'!$F$6,0) -> 1 | F10: =IF(AND(N('Hiring plan'!$F$6)>0,F$3>='Hiring plan'!$G$6,F$3<=IF('Hiring plan'!$H$6="",999,'Hiring plan'!$H$6)),'Hiring plan'!$F$6,0) -> 1 | G10: =IF(AND(N('Hiring plan'!$F$6)>0,G$3>='Hiring plan'!$G$6,G$3<=IF('Hiring plan'!$H$6="",999,'Hiring plan'!$H$6)),'Hiring plan'!$F$6,0) -> 1 | H10: =IF(AND(N('Hiring plan'!$F$6)>0,H$3>='Hiring plan'!$G$6,H$3<=IF('Hiring plan'!$H$6="",999,'Hiring plan'!$H$6)),'Hiring plan'!$F$6,0) -> 1 | I10: =IF(AND(N('Hiring plan'!$F$6)>0,I$3>='Hiring plan'!$G$6,I$3<=IF('Hiring plan'!$H$6="",999,'Hiring plan'!$H$6)),'Hiring plan'!$F$6,0) -> 1 | J10: =IF(AND(N('Hiring plan'!$F$6)>0,J$3>='Hiring plan'!$G$6,J$3<=IF('Hiring plan'!$H$6="",999,'Hiring plan'!$H$6)),'Hiring plan'!$F$6,0) -> 1 | K10: =IF(AND(N('Hiring plan'!$F$6)>0,K$3>='Hiring plan'!$G$6,K$3<=IF('Hiring plan'!$H$6="",999,'Hiring plan'!$H$6)),'Hiring plan'!$F$6,0) -> 1 | L10: =IF(AND(N('Hiring plan'!$F$6)>0,L$3>='Hiring plan'!$G$6,L$3<=IF('Hiring plan'!$H$6="",999,'Hiring plan'!$H$6)),'Hiring plan'!$F$6,0) -> 1 | ... BL10: =IF(AND(N('Hiring plan'!$F$6)>0,BL$3>='Hiring plan'!$G$6,BL$3<=IF('Hiring plan'!$H$6="",999,'Hiring plan'!$H$6)),'Hiring plan'!$F$6,0) -> 1
A11: =IF('Hiring plan'!$C$7="","(spare line 3)",'Hiring plan'!$C$7&" · "&'Hiring plan'!$D$7) -> Financial expert (finance, partners, credit lead) · SN | B11: people | D11: =MAX(E11:BL11) -> 1 | E11: =IF(AND(N('Hiring plan'!$F$7)>0,E$3>='Hiring plan'!$G$7,E$3<=IF('Hiring plan'!$H$7="",999,'Hiring plan'!$H$7)),'Hiring plan'!$F$7,0) -> 1 | F11: =IF(AND(N('Hiring plan'!$F$7)>0,F$3>='Hiring plan'!$G$7,F$3<=IF('Hiring plan'!$H$7="",999,'Hiring plan'!$H$7)),'Hiring plan'!$F$7,0) -> 1 | G11: =IF(AND(N('Hiring plan'!$F$7)>0,G$3>='Hiring plan'!$G$7,G$3<=IF('Hiring plan'!$H$7="",999,'Hiring plan'!$H$7)),'Hiring plan'!$F$7,0) -> 1 | H11: =IF(AND(N('Hiring plan'!$F$7)>0,H$3>='Hiring plan'!$G$7,H$3<=IF('Hiring plan'!$H$7="",999,'Hiring plan'!$H$7)),'Hiring plan'!$F$7,0) -> 1 | I11: =IF(AND(N('Hiring plan'!$F$7)>0,I$3>='Hiring plan'!$G$7,I$3<=IF('Hiring plan'!$H$7="",999,'Hiring plan'!$H$7)),'Hiring plan'!$F$7,0) -> 1 | J11: =IF(AND(N('Hiring plan'!$F$7)>0,J$3>='Hiring plan'!$G$7,J$3<=IF('Hiring plan'!$H$7="",999,'Hiring plan'!$H$7)),'Hiring plan'!$F$7,0) -> 1 | K11: =IF(AND(N('Hiring plan'!$F$7)>0,K$3>='Hiring plan'!$G$7,K$3<=IF('Hiring plan'!$H$7="",999,'Hiring plan'!$H$7)),'Hiring plan'!$F$7,0) -> 1 | L11: =IF(AND(N('Hiring plan'!$F$7)>0,L$3>='Hiring plan'!$G$7,L$3<=IF('Hiring plan'!$H$7="",999,'Hiring plan'!$H$7)),'Hiring plan'!$F$7,0) -> 1 | ... BL11: =IF(AND(N('Hiring plan'!$F$7)>0,BL$3>='Hiring plan'!$G$7,BL$3<=IF('Hiring plan'!$H$7="",999,'Hiring plan'!$H$7)),'Hiring plan'!$F$7,0) -> 1
A12: =IF('Hiring plan'!$C$8="","(spare line 4)",'Hiring plan'!$C$8&" · "&'Hiring plan'!$D$8) -> Sales lead (also sells; incl. bonus) · SN | B12: people | D12: =MAX(E12:BL12) -> 1 | E12: =IF(AND(N('Hiring plan'!$F$8)>0,E$3>='Hiring plan'!$G$8,E$3<=IF('Hiring plan'!$H$8="",999,'Hiring plan'!$H$8)),'Hiring plan'!$F$8,0) -> 1 | F12: =IF(AND(N('Hiring plan'!$F$8)>0,F$3>='Hiring plan'!$G$8,F$3<=IF('Hiring plan'!$H$8="",999,'Hiring plan'!$H$8)),'Hiring plan'!$F$8,0) -> 1 | G12: =IF(AND(N('Hiring plan'!$F$8)>0,G$3>='Hiring plan'!$G$8,G$3<=IF('Hiring plan'!$H$8="",999,'Hiring plan'!$H$8)),'Hiring plan'!$F$8,0) -> 1 | H12: =IF(AND(N('Hiring plan'!$F$8)>0,H$3>='Hiring plan'!$G$8,H$3<=IF('Hiring plan'!$H$8="",999,'Hiring plan'!$H$8)),'Hiring plan'!$F$8,0) -> 1 | I12: =IF(AND(N('Hiring plan'!$F$8)>0,I$3>='Hiring plan'!$G$8,I$3<=IF('Hiring plan'!$H$8="",999,'Hiring plan'!$H$8)),'Hiring plan'!$F$8,0) -> 1 | J12: =IF(AND(N('Hiring plan'!$F$8)>0,J$3>='Hiring plan'!$G$8,J$3<=IF('Hiring plan'!$H$8="",999,'Hiring plan'!$H$8)),'Hiring plan'!$F$8,0) -> 1 | K12: =IF(AND(N('Hiring plan'!$F$8)>0,K$3>='Hiring plan'!$G$8,K$3<=IF('Hiring plan'!$H$8="",999,'Hiring plan'!$H$8)),'Hiring plan'!$F$8,0) -> 1 | L12: =IF(AND(N('Hiring plan'!$F$8)>0,L$3>='Hiring plan'!$G$8,L$3<=IF('Hiring plan'!$H$8="",999,'Hiring plan'!$H$8)),'Hiring plan'!$F$8,0) -> 1 | ... BL12: =IF(AND(N('Hiring plan'!$F$8)>0,BL$3>='Hiring plan'!$G$8,BL$3<=IF('Hiring plan'!$H$8="",999,'Hiring plan'!$H$8)),'Hiring plan'!$F$8,0) -> 1
A13: =IF('Hiring plan'!$C$9="","(spare line 5)",'Hiring plan'!$C$9&" · "&'Hiring plan'!$D$9) -> Marketing manager (senior) · SN | B13: people | D13: =MAX(E13:BL13) -> 1 | E13: =IF(AND(N('Hiring plan'!$F$9)>0,E$3>='Hiring plan'!$G$9,E$3<=IF('Hiring plan'!$H$9="",999,'Hiring plan'!$H$9)),'Hiring plan'!$F$9,0) -> 0 | F13: =IF(AND(N('Hiring plan'!$F$9)>0,F$3>='Hiring plan'!$G$9,F$3<=IF('Hiring plan'!$H$9="",999,'Hiring plan'!$H$9)),'Hiring plan'!$F$9,0) -> 0 | G13: =IF(AND(N('Hiring plan'!$F$9)>0,G$3>='Hiring plan'!$G$9,G$3<=IF('Hiring plan'!$H$9="",999,'Hiring plan'!$H$9)),'Hiring plan'!$F$9,0) -> 0 | H13: =IF(AND(N('Hiring plan'!$F$9)>0,H$3>='Hiring plan'!$G$9,H$3<=IF('Hiring plan'!$H$9="",999,'Hiring plan'!$H$9)),'Hiring plan'!$F$9,0) -> 1 | I13: =IF(AND(N('Hiring plan'!$F$9)>0,I$3>='Hiring plan'!$G$9,I$3<=IF('Hiring plan'!$H$9="",999,'Hiring plan'!$H$9)),'Hiring plan'!$F$9,0) -> 1 | J13: =IF(AND(N('Hiring plan'!$F$9)>0,J$3>='Hiring plan'!$G$9,J$3<=IF('Hiring plan'!$H$9="",999,'Hiring plan'!$H$9)),'Hiring plan'!$F$9,0) -> 1 | K13: =IF(AND(N('Hiring plan'!$F$9)>0,K$3>='Hiring plan'!$G$9,K$3<=IF('Hiring plan'!$H$9="",999,'Hiring plan'!$H$9)),'Hiring plan'!$F$9,0) -> 1 | L13: =IF(AND(N('Hiring plan'!$F$9)>0,L$3>='Hiring plan'!$G$9,L$3<=IF('Hiring plan'!$H$9="",999,'Hiring plan'!$H$9)),'Hiring plan'!$F$9,0) -> 1 | ... BL13: =IF(AND(N('Hiring plan'!$F$9)>0,BL$3>='Hiring plan'!$G$9,BL$3<=IF('Hiring plan'!$H$9="",999,'Hiring plan'!$H$9)),'Hiring plan'!$F$9,0) -> 1
A14: =IF('Hiring plan'!$C$10="","(spare line 6)",'Hiring plan'!$C$10&" · "&'Hiring plan'!$D$10) -> Marketing officer (junior) · SN | B14: people | D14: =MAX(E14:BL14) -> 1 | E14: =IF(AND(N('Hiring plan'!$F$10)>0,E$3>='Hiring plan'!$G$10,E$3<=IF('Hiring plan'!$H$10="",999,'Hiring plan'!$H$10)),'Hiring plan'!$F$10,0) -> 0 | F14: =IF(AND(N('Hiring plan'!$F$10)>0,F$3>='Hiring plan'!$G$10,F$3<=IF('Hiring plan'!$H$10="",999,'Hiring plan'!$H$10)),'Hiring plan'!$F$10,0) -> 0 | G14: =IF(AND(N('Hiring plan'!$F$10)>0,G$3>='Hiring plan'!$G$10,G$3<=IF('Hiring plan'!$H$10="",999,'Hiring plan'!$H$10)),'Hiring plan'!$F$10,0) -> 0 | H14: =IF(AND(N('Hiring plan'!$F$10)>0,H$3>='Hiring plan'!$G$10,H$3<=IF('Hiring plan'!$H$10="",999,'Hiring plan'!$H$10)),'Hiring plan'!$F$10,0) -> 0 | I14: =IF(AND(N('Hiring plan'!$F$10)>0,I$3>='Hiring plan'!$G$10,I$3<=IF('Hiring plan'!$H$10="",999,'Hiring plan'!$H$10)),'Hiring plan'!$F$10,0) -> 1 | J14: =IF(AND(N('Hiring plan'!$F$10)>0,J$3>='Hiring plan'!$G$10,J$3<=IF('Hiring plan'!$H$10="",999,'Hiring plan'!$H$10)),'Hiring plan'!$F$10,0) -> 1 | K14: =IF(AND(N('Hiring plan'!$F$10)>0,K$3>='Hiring plan'!$G$10,K$3<=IF('Hiring plan'!$H$10="",999,'Hiring plan'!$H$10)),'Hiring plan'!$F$10,0) -> 1 | L14: =IF(AND(N('Hiring plan'!$F$10)>0,L$3>='Hiring plan'!$G$10,L$3<=IF('Hiring plan'!$H$10="",999,'Hiring plan'!$H$10)),'Hiring plan'!$F$10,0) -> 1 | ... BL14: =IF(AND(N('Hiring plan'!$F$10)>0,BL$3>='Hiring plan'!$G$10,BL$3<=IF('Hiring plan'!$H$10="",999,'Hiring plan'!$H$10)),'Hiring plan'!$F$10,0) -> 1
A15: =IF('Hiring plan'!$C$11="","(spare line 7)",'Hiring plan'!$C$11&" · "&'Hiring plan'!$D$11) -> Country manager, Abidjan · CI | B15: people | D15: =MAX(E15:BL15) -> 1 | E15: =IF(AND(N('Hiring plan'!$F$11)>0,E$3>='Hiring plan'!$G$11,E$3<=IF('Hiring plan'!$H$11="",999,'Hiring plan'!$H$11)),'Hiring plan'!$F$11,0) -> 0 | F15: =IF(AND(N('Hiring plan'!$F$11)>0,F$3>='Hiring plan'!$G$11,F$3<=IF('Hiring plan'!$H$11="",999,'Hiring plan'!$H$11)),'Hiring plan'!$F$11,0) -> 0 | G15: =IF(AND(N('Hiring plan'!$F$11)>0,G$3>='Hiring plan'!$G$11,G$3<=IF('Hiring plan'!$H$11="",999,'Hiring plan'!$H$11)),'Hiring plan'!$F$11,0) -> 0 | H15: =IF(AND(N('Hiring plan'!$F$11)>0,H$3>='Hiring plan'!$G$11,H$3<=IF('Hiring plan'!$H$11="",999,'Hiring plan'!$H$11)),'Hiring plan'!$F$11,0) -> 0 | I15: =IF(AND(N('Hiring plan'!$F$11)>0,I$3>='Hiring plan'!$G$11,I$3<=IF('Hiring plan'!$H$11="",999,'Hiring plan'!$H$11)),'Hiring plan'!$F$11,0) -> 0 | J15: =IF(AND(N('Hiring plan'!$F$11)>0,J$3>='Hiring plan'!$G$11,J$3<=IF('Hiring plan'!$H$11="",999,'Hiring plan'!$H$11)),'Hiring plan'!$F$11,0) -> 0 | K15: =IF(AND(N('Hiring plan'!$F$11)>0,K$3>='Hiring plan'!$G$11,K$3<=IF('Hiring plan'!$H$11="",999,'Hiring plan'!$H$11)),'Hiring plan'!$F$11,0) -> 0 | L15: =IF(AND(N('Hiring plan'!$F$11)>0,L$3>='Hiring plan'!$G$11,L$3<=IF('Hiring plan'!$H$11="",999,'Hiring plan'!$H$11)),'Hiring plan'!$F$11,0) -> 0 | ... BL15: =IF(AND(N('Hiring plan'!$F$11)>0,BL$3>='Hiring plan'!$G$11,BL$3<=IF('Hiring plan'!$H$11="",999,'Hiring plan'!$H$11)),'Hiring plan'!$F$11,0) -> 1
A16: =IF('Hiring plan'!$C$12="","(spare line 8)",'Hiring plan'!$C$12&" · "&'Hiring plan'!$D$12) -> Compliance officer (AML/CFT) · SN | B16: people | D16: =MAX(E16:BL16) -> 1 | E16: =IF(AND(N('Hiring plan'!$F$12)>0,E$3>='Hiring plan'!$G$12,E$3<=IF('Hiring plan'!$H$12="",999,'Hiring plan'!$H$12)),'Hiring plan'!$F$12,0) -> 0 | F16: =IF(AND(N('Hiring plan'!$F$12)>0,F$3>='Hiring plan'!$G$12,F$3<=IF('Hiring plan'!$H$12="",999,'Hiring plan'!$H$12)),'Hiring plan'!$F$12,0) -> 0 | G16: =IF(AND(N('Hiring plan'!$F$12)>0,G$3>='Hiring plan'!$G$12,G$3<=IF('Hiring plan'!$H$12="",999,'Hiring plan'!$H$12)),'Hiring plan'!$F$12,0) -> 0 | H16: =IF(AND(N('Hiring plan'!$F$12)>0,H$3>='Hiring plan'!$G$12,H$3<=IF('Hiring plan'!$H$12="",999,'Hiring plan'!$H$12)),'Hiring plan'!$F$12,0) -> 0 | I16: =IF(AND(N('Hiring plan'!$F$12)>0,I$3>='Hiring plan'!$G$12,I$3<=IF('Hiring plan'!$H$12="",999,'Hiring plan'!$H$12)),'Hiring plan'!$F$12,0) -> 0 | J16: =IF(AND(N('Hiring plan'!$F$12)>0,J$3>='Hiring plan'!$G$12,J$3<=IF('Hiring plan'!$H$12="",999,'Hiring plan'!$H$12)),'Hiring plan'!$F$12,0) -> 0 | K16: =IF(AND(N('Hiring plan'!$F$12)>0,K$3>='Hiring plan'!$G$12,K$3<=IF('Hiring plan'!$H$12="",999,'Hiring plan'!$H$12)),'Hiring plan'!$F$12,0) -> 0 | L16: =IF(AND(N('Hiring plan'!$F$12)>0,L$3>='Hiring plan'!$G$12,L$3<=IF('Hiring plan'!$H$12="",999,'Hiring plan'!$H$12)),'Hiring plan'!$F$12,0) -> 0 | ... BL16: =IF(AND(N('Hiring plan'!$F$12)>0,BL$3>='Hiring plan'!$G$12,BL$3<=IF('Hiring plan'!$H$12="",999,'Hiring plan'!$H$12)),'Hiring plan'!$F$12,0) -> 1
A17: =IF('Hiring plan'!$C$13="","(spare line 9)",'Hiring plan'!$C$13&" · "&'Hiring plan'!$D$13) -> (spare line 9) | B17: people | D17: =MAX(E17:BL17) -> 0 | E17: =IF(AND(N('Hiring plan'!$F$13)>0,E$3>='Hiring plan'!$G$13,E$3<=IF('Hiring plan'!$H$13="",999,'Hiring plan'!$H$13)),'Hiring plan'!$F$13,0) -> 0 | F17: =IF(AND(N('Hiring plan'!$F$13)>0,F$3>='Hiring plan'!$G$13,F$3<=IF('Hiring plan'!$H$13="",999,'Hiring plan'!$H$13)),'Hiring plan'!$F$13,0) -> 0 | G17: =IF(AND(N('Hiring plan'!$F$13)>0,G$3>='Hiring plan'!$G$13,G$3<=IF('Hiring plan'!$H$13="",999,'Hiring plan'!$H$13)),'Hiring plan'!$F$13,0) -> 0 | H17: =IF(AND(N('Hiring plan'!$F$13)>0,H$3>='Hiring plan'!$G$13,H$3<=IF('Hiring plan'!$H$13="",999,'Hiring plan'!$H$13)),'Hiring plan'!$F$13,0) -> 0 | I17: =IF(AND(N('Hiring plan'!$F$13)>0,I$3>='Hiring plan'!$G$13,I$3<=IF('Hiring plan'!$H$13="",999,'Hiring plan'!$H$13)),'Hiring plan'!$F$13,0) -> 0 | J17: =IF(AND(N('Hiring plan'!$F$13)>0,J$3>='Hiring plan'!$G$13,J$3<=IF('Hiring plan'!$H$13="",999,'Hiring plan'!$H$13)),'Hiring plan'!$F$13,0) -> 0 | K17: =IF(AND(N('Hiring plan'!$F$13)>0,K$3>='Hiring plan'!$G$13,K$3<=IF('Hiring plan'!$H$13="",999,'Hiring plan'!$H$13)),'Hiring plan'!$F$13,0) -> 0 | L17: =IF(AND(N('Hiring plan'!$F$13)>0,L$3>='Hiring plan'!$G$13,L$3<=IF('Hiring plan'!$H$13="",999,'Hiring plan'!$H$13)),'Hiring plan'!$F$13,0) -> 0 | ... BL17: =IF(AND(N('Hiring plan'!$F$13)>0,BL$3>='Hiring plan'!$G$13,BL$3<=IF('Hiring plan'!$H$13="",999,'Hiring plan'!$H$13)),'Hiring plan'!$F$13,0) -> 0
A18: =IF('Hiring plan'!$C$14="","(spare line 10)",'Hiring plan'!$C$14&" · "&'Hiring plan'!$D$14) -> (spare line 10) | B18: people | D18: =MAX(E18:BL18) -> 0 | E18: =IF(AND(N('Hiring plan'!$F$14)>0,E$3>='Hiring plan'!$G$14,E$3<=IF('Hiring plan'!$H$14="",999,'Hiring plan'!$H$14)),'Hiring plan'!$F$14,0) -> 0 | F18: =IF(AND(N('Hiring plan'!$F$14)>0,F$3>='Hiring plan'!$G$14,F$3<=IF('Hiring plan'!$H$14="",999,'Hiring plan'!$H$14)),'Hiring plan'!$F$14,0) -> 0 | G18: =IF(AND(N('Hiring plan'!$F$14)>0,G$3>='Hiring plan'!$G$14,G$3<=IF('Hiring plan'!$H$14="",999,'Hiring plan'!$H$14)),'Hiring plan'!$F$14,0) -> 0 | H18: =IF(AND(N('Hiring plan'!$F$14)>0,H$3>='Hiring plan'!$G$14,H$3<=IF('Hiring plan'!$H$14="",999,'Hiring plan'!$H$14)),'Hiring plan'!$F$14,0) -> 0 | I18: =IF(AND(N('Hiring plan'!$F$14)>0,I$3>='Hiring plan'!$G$14,I$3<=IF('Hiring plan'!$H$14="",999,'Hiring plan'!$H$14)),'Hiring plan'!$F$14,0) -> 0 | J18: =IF(AND(N('Hiring plan'!$F$14)>0,J$3>='Hiring plan'!$G$14,J$3<=IF('Hiring plan'!$H$14="",999,'Hiring plan'!$H$14)),'Hiring plan'!$F$14,0) -> 0 | K18: =IF(AND(N('Hiring plan'!$F$14)>0,K$3>='Hiring plan'!$G$14,K$3<=IF('Hiring plan'!$H$14="",999,'Hiring plan'!$H$14)),'Hiring plan'!$F$14,0) -> 0 | L18: =IF(AND(N('Hiring plan'!$F$14)>0,L$3>='Hiring plan'!$G$14,L$3<=IF('Hiring plan'!$H$14="",999,'Hiring plan'!$H$14)),'Hiring plan'!$F$14,0) -> 0 | ... BL18: =IF(AND(N('Hiring plan'!$F$14)>0,BL$3>='Hiring plan'!$G$14,BL$3<=IF('Hiring plan'!$H$14="",999,'Hiring plan'!$H$14)),'Hiring plan'!$F$14,0) -> 0
A19: =IF('Hiring plan'!$C$15="","(spare line 11)",'Hiring plan'!$C$15&" · "&'Hiring plan'!$D$15) -> (spare line 11) | B19: people | D19: =MAX(E19:BL19) -> 0 | E19: =IF(AND(N('Hiring plan'!$F$15)>0,E$3>='Hiring plan'!$G$15,E$3<=IF('Hiring plan'!$H$15="",999,'Hiring plan'!$H$15)),'Hiring plan'!$F$15,0) -> 0 | F19: =IF(AND(N('Hiring plan'!$F$15)>0,F$3>='Hiring plan'!$G$15,F$3<=IF('Hiring plan'!$H$15="",999,'Hiring plan'!$H$15)),'Hiring plan'!$F$15,0) -> 0 | G19: =IF(AND(N('Hiring plan'!$F$15)>0,G$3>='Hiring plan'!$G$15,G$3<=IF('Hiring plan'!$H$15="",999,'Hiring plan'!$H$15)),'Hiring plan'!$F$15,0) -> 0 | H19: =IF(AND(N('Hiring plan'!$F$15)>0,H$3>='Hiring plan'!$G$15,H$3<=IF('Hiring plan'!$H$15="",999,'Hiring plan'!$H$15)),'Hiring plan'!$F$15,0) -> 0 | I19: =IF(AND(N('Hiring plan'!$F$15)>0,I$3>='Hiring plan'!$G$15,I$3<=IF('Hiring plan'!$H$15="",999,'Hiring plan'!$H$15)),'Hiring plan'!$F$15,0) -> 0 | J19: =IF(AND(N('Hiring plan'!$F$15)>0,J$3>='Hiring plan'!$G$15,J$3<=IF('Hiring plan'!$H$15="",999,'Hiring plan'!$H$15)),'Hiring plan'!$F$15,0) -> 0 | K19: =IF(AND(N('Hiring plan'!$F$15)>0,K$3>='Hiring plan'!$G$15,K$3<=IF('Hiring plan'!$H$15="",999,'Hiring plan'!$H$15)),'Hiring plan'!$F$15,0) -> 0 | L19: =IF(AND(N('Hiring plan'!$F$15)>0,L$3>='Hiring plan'!$G$15,L$3<=IF('Hiring plan'!$H$15="",999,'Hiring plan'!$H$15)),'Hiring plan'!$F$15,0) -> 0 | ... BL19: =IF(AND(N('Hiring plan'!$F$15)>0,BL$3>='Hiring plan'!$G$15,BL$3<=IF('Hiring plan'!$H$15="",999,'Hiring plan'!$H$15)),'Hiring plan'!$F$15,0) -> 0
A20: =IF('Hiring plan'!$C$16="","(spare line 12)",'Hiring plan'!$C$16&" · "&'Hiring plan'!$D$16) -> (spare line 12) | B20: people | D20: =MAX(E20:BL20) -> 0 | E20: =IF(AND(N('Hiring plan'!$F$16)>0,E$3>='Hiring plan'!$G$16,E$3<=IF('Hiring plan'!$H$16="",999,'Hiring plan'!$H$16)),'Hiring plan'!$F$16,0) -> 0 | F20: =IF(AND(N('Hiring plan'!$F$16)>0,F$3>='Hiring plan'!$G$16,F$3<=IF('Hiring plan'!$H$16="",999,'Hiring plan'!$H$16)),'Hiring plan'!$F$16,0) -> 0 | G20: =IF(AND(N('Hiring plan'!$F$16)>0,G$3>='Hiring plan'!$G$16,G$3<=IF('Hiring plan'!$H$16="",999,'Hiring plan'!$H$16)),'Hiring plan'!$F$16,0) -> 0 | H20: =IF(AND(N('Hiring plan'!$F$16)>0,H$3>='Hiring plan'!$G$16,H$3<=IF('Hiring plan'!$H$16="",999,'Hiring plan'!$H$16)),'Hiring plan'!$F$16,0) -> 0 | I20: =IF(AND(N('Hiring plan'!$F$16)>0,I$3>='Hiring plan'!$G$16,I$3<=IF('Hiring plan'!$H$16="",999,'Hiring plan'!$H$16)),'Hiring plan'!$F$16,0) -> 0 | J20: =IF(AND(N('Hiring plan'!$F$16)>0,J$3>='Hiring plan'!$G$16,J$3<=IF('Hiring plan'!$H$16="",999,'Hiring plan'!$H$16)),'Hiring plan'!$F$16,0) -> 0 | K20: =IF(AND(N('Hiring plan'!$F$16)>0,K$3>='Hiring plan'!$G$16,K$3<=IF('Hiring plan'!$H$16="",999,'Hiring plan'!$H$16)),'Hiring plan'!$F$16,0) -> 0 | L20: =IF(AND(N('Hiring plan'!$F$16)>0,L$3>='Hiring plan'!$G$16,L$3<=IF('Hiring plan'!$H$16="",999,'Hiring plan'!$H$16)),'Hiring plan'!$F$16,0) -> 0 | ... BL20: =IF(AND(N('Hiring plan'!$F$16)>0,BL$3>='Hiring plan'!$G$16,BL$3<=IF('Hiring plan'!$H$16="",999,'Hiring plan'!$H$16)),'Hiring plan'!$F$16,0) -> 0
A21: =IF('Hiring plan'!$C$17="","(spare line 13)",'Hiring plan'!$C$17&" · "&'Hiring plan'!$D$17) -> (spare line 13) | B21: people | D21: =MAX(E21:BL21) -> 0 | E21: =IF(AND(N('Hiring plan'!$F$17)>0,E$3>='Hiring plan'!$G$17,E$3<=IF('Hiring plan'!$H$17="",999,'Hiring plan'!$H$17)),'Hiring plan'!$F$17,0) -> 0 | F21: =IF(AND(N('Hiring plan'!$F$17)>0,F$3>='Hiring plan'!$G$17,F$3<=IF('Hiring plan'!$H$17="",999,'Hiring plan'!$H$17)),'Hiring plan'!$F$17,0) -> 0 | G21: =IF(AND(N('Hiring plan'!$F$17)>0,G$3>='Hiring plan'!$G$17,G$3<=IF('Hiring plan'!$H$17="",999,'Hiring plan'!$H$17)),'Hiring plan'!$F$17,0) -> 0 | H21: =IF(AND(N('Hiring plan'!$F$17)>0,H$3>='Hiring plan'!$G$17,H$3<=IF('Hiring plan'!$H$17="",999,'Hiring plan'!$H$17)),'Hiring plan'!$F$17,0) -> 0 | I21: =IF(AND(N('Hiring plan'!$F$17)>0,I$3>='Hiring plan'!$G$17,I$3<=IF('Hiring plan'!$H$17="",999,'Hiring plan'!$H$17)),'Hiring plan'!$F$17,0) -> 0 | J21: =IF(AND(N('Hiring plan'!$F$17)>0,J$3>='Hiring plan'!$G$17,J$3<=IF('Hiring plan'!$H$17="",999,'Hiring plan'!$H$17)),'Hiring plan'!$F$17,0) -> 0 | K21: =IF(AND(N('Hiring plan'!$F$17)>0,K$3>='Hiring plan'!$G$17,K$3<=IF('Hiring plan'!$H$17="",999,'Hiring plan'!$H$17)),'Hiring plan'!$F$17,0) -> 0 | L21: =IF(AND(N('Hiring plan'!$F$17)>0,L$3>='Hiring plan'!$G$17,L$3<=IF('Hiring plan'!$H$17="",999,'Hiring plan'!$H$17)),'Hiring plan'!$F$17,0) -> 0 | ... BL21: =IF(AND(N('Hiring plan'!$F$17)>0,BL$3>='Hiring plan'!$G$17,BL$3<=IF('Hiring plan'!$H$17="",999,'Hiring plan'!$H$17)),'Hiring plan'!$F$17,0) -> 0
A22: =IF('Hiring plan'!$C$18="","(spare line 14)",'Hiring plan'!$C$18&" · "&'Hiring plan'!$D$18) -> (spare line 14) | B22: people | D22: =MAX(E22:BL22) -> 0 | E22: =IF(AND(N('Hiring plan'!$F$18)>0,E$3>='Hiring plan'!$G$18,E$3<=IF('Hiring plan'!$H$18="",999,'Hiring plan'!$H$18)),'Hiring plan'!$F$18,0) -> 0 | F22: =IF(AND(N('Hiring plan'!$F$18)>0,F$3>='Hiring plan'!$G$18,F$3<=IF('Hiring plan'!$H$18="",999,'Hiring plan'!$H$18)),'Hiring plan'!$F$18,0) -> 0 | G22: =IF(AND(N('Hiring plan'!$F$18)>0,G$3>='Hiring plan'!$G$18,G$3<=IF('Hiring plan'!$H$18="",999,'Hiring plan'!$H$18)),'Hiring plan'!$F$18,0) -> 0 | H22: =IF(AND(N('Hiring plan'!$F$18)>0,H$3>='Hiring plan'!$G$18,H$3<=IF('Hiring plan'!$H$18="",999,'Hiring plan'!$H$18)),'Hiring plan'!$F$18,0) -> 0 | I22: =IF(AND(N('Hiring plan'!$F$18)>0,I$3>='Hiring plan'!$G$18,I$3<=IF('Hiring plan'!$H$18="",999,'Hiring plan'!$H$18)),'Hiring plan'!$F$18,0) -> 0 | J22: =IF(AND(N('Hiring plan'!$F$18)>0,J$3>='Hiring plan'!$G$18,J$3<=IF('Hiring plan'!$H$18="",999,'Hiring plan'!$H$18)),'Hiring plan'!$F$18,0) -> 0 | K22: =IF(AND(N('Hiring plan'!$F$18)>0,K$3>='Hiring plan'!$G$18,K$3<=IF('Hiring plan'!$H$18="",999,'Hiring plan'!$H$18)),'Hiring plan'!$F$18,0) -> 0 | L22: =IF(AND(N('Hiring plan'!$F$18)>0,L$3>='Hiring plan'!$G$18,L$3<=IF('Hiring plan'!$H$18="",999,'Hiring plan'!$H$18)),'Hiring plan'!$F$18,0) -> 0 | ... BL22: =IF(AND(N('Hiring plan'!$F$18)>0,BL$3>='Hiring plan'!$G$18,BL$3<=IF('Hiring plan'!$H$18="",999,'Hiring plan'!$H$18)),'Hiring plan'!$F$18,0) -> 0
A23: =IF('Hiring plan'!$C$19="","(spare line 15)",'Hiring plan'!$C$19&" · "&'Hiring plan'!$D$19) -> (spare line 15) | B23: people | D23: =MAX(E23:BL23) -> 0 | E23: =IF(AND(N('Hiring plan'!$F$19)>0,E$3>='Hiring plan'!$G$19,E$3<=IF('Hiring plan'!$H$19="",999,'Hiring plan'!$H$19)),'Hiring plan'!$F$19,0) -> 0 | F23: =IF(AND(N('Hiring plan'!$F$19)>0,F$3>='Hiring plan'!$G$19,F$3<=IF('Hiring plan'!$H$19="",999,'Hiring plan'!$H$19)),'Hiring plan'!$F$19,0) -> 0 | G23: =IF(AND(N('Hiring plan'!$F$19)>0,G$3>='Hiring plan'!$G$19,G$3<=IF('Hiring plan'!$H$19="",999,'Hiring plan'!$H$19)),'Hiring plan'!$F$19,0) -> 0 | H23: =IF(AND(N('Hiring plan'!$F$19)>0,H$3>='Hiring plan'!$G$19,H$3<=IF('Hiring plan'!$H$19="",999,'Hiring plan'!$H$19)),'Hiring plan'!$F$19,0) -> 0 | I23: =IF(AND(N('Hiring plan'!$F$19)>0,I$3>='Hiring plan'!$G$19,I$3<=IF('Hiring plan'!$H$19="",999,'Hiring plan'!$H$19)),'Hiring plan'!$F$19,0) -> 0 | J23: =IF(AND(N('Hiring plan'!$F$19)>0,J$3>='Hiring plan'!$G$19,J$3<=IF('Hiring plan'!$H$19="",999,'Hiring plan'!$H$19)),'Hiring plan'!$F$19,0) -> 0 | K23: =IF(AND(N('Hiring plan'!$F$19)>0,K$3>='Hiring plan'!$G$19,K$3<=IF('Hiring plan'!$H$19="",999,'Hiring plan'!$H$19)),'Hiring plan'!$F$19,0) -> 0 | L23: =IF(AND(N('Hiring plan'!$F$19)>0,L$3>='Hiring plan'!$G$19,L$3<=IF('Hiring plan'!$H$19="",999,'Hiring plan'!$H$19)),'Hiring plan'!$F$19,0) -> 0 | ... BL23: =IF(AND(N('Hiring plan'!$F$19)>0,BL$3>='Hiring plan'!$G$19,BL$3<=IF('Hiring plan'!$H$19="",999,'Hiring plan'!$H$19)),'Hiring plan'!$F$19,0) -> 0
